Workbook

Sheet 收货记录查询
A1: 业务类型 | B1: 分类 | C1: 操作日期 | D1: =E1&F1&G1 | E1: 操作时间 | F1: 仓库 | G1: 货主 | H1: 库存地点 | I1: 指令编号 | J1: 指令行项 | K1: 物料编码 | L1: 物料描述 | M1: 厂商 | N1: 产品型号简称 | O1: 物料计费类型 | P1: 确认状态 | Q1: 移动方向 | R1: 移动类型 | S1: 特殊库存 | T1: 特殊库存编号 | U1: 批次号 | V1: 目的存储类型 | W1: 目的仓位 | X1: 目的存储单元编号 | Y1: 源数量 | Z1: 确认数量 | AA1: 确认差异数量 | AB1: 单位 | AC1: 用户 | AD1: 供应商 | AE1: 转储需求编号 | AF1: 订单号 | AG1: 采购订单行号 | AH1: 修改日期 | AI1: 修改用户 | AJ1: 创建日期 | AK1: 创建用户
A2: =_xlfn.XLOOKUP(D2,匹配条件!K:K,匹配条件!J:J) | B2: {=_xlfn.IFS(O2="10-终端","手机",O2="20-配件","配件",O2="30-促销品","促销品",O2="40-3C产品","多形态")} | C2: =INT(E2) | D2: =F2&G2 | E2: 2026-06-22 21:32:17 | F2: 广东华为品牌专仓(科捷) | G2: 4400 | H2: 2354 | I2: 1001520944 | J2: 000010|001 | K2: 10064829067000L0 | L2: 华为_CRS-AL00 12+256,晴空蓝,12+256G,全网通,销售用机 | M2: 华为 | N2: nova 16 Pro 12+256 | O2: 10-终端 | P2: 创建 | Q2: 入库 | R2: 10 | S2: X | T2: 0006112176 | U2: 2026 | V2: SHKQ | W2: REMAIN | X2: 1677 | Y2: 50 | Z2: 0 | AA2: 50 | AB2: 个 | AC2: 赖锦燕 | AD2: X | AE2: SH26062202248 | AF2: 4501507511 | AG2: 000010|001 | AH2: 2026-06-22 21:32:17 | AI2: 赖锦燕 | AJ2: 2026-06-22 21:32:17 | AK2: 赖锦燕

Sheet 总库存
A1: 业务类型 | B1: 分类 | C1: =F1&G1&H1 | D1: =A1&I1 | E1: SKU | F1: 仓库 | G1: 货主 | H1: 库存地点 | I1: 物料编码 | J1: 物料描述 | K1: 是否冻结 | L1: 特殊库存 | M1: 特殊库存编码 | N1: 总数量 | O1: 可用数量 | P1: 占用数量 | Q1: 收货数量 | R1: 存货数量 | S1: 中间数量 | T1: 外部编码 | U1: 品牌名称 | V1: 产品型号简称 | W1: 物料计费类型
A2: =_xlfn.XLOOKUP(C2,匹配条件!K:K,匹配条件!J:J) | B2: {=_xlfn.IFS(W2="10-终端","手机",W2="20-配件","配件",W2="30-促销品","促销品",W2="40-3C产品","多形态")} | C2: =F2&G2 | D2: =IF(R2=0,0,A2&I2) | E2: =COUNTIF($D$2:D2,D2) | F2: 总部深圳通用总仓(科捷) | G2: 1000 | H2: 2009 | I2: 1006241008000100 | J2: 华为_ASN-AL10,蓝色,通用内存单电单充,公开版,销售用机 | K2: 否 | L2: X | M2: X | N2: 90989 | O2: 90989 | P2: 0 | Q2: 0 | R2: 90989 | S2: 0 | T2: 1006241008000100 | U2: 华为 | V2: 华为儿童手表 4 PRO | W2: 40-3C产品

Sheet 出库全流程
A1: 业务类型 | B1: 分类 | C1: 数量 | D1: 仓库货主库存地点 | E1: 发货仓库 | F1: 移出货主 | G1: 移出库存地 | H1: 指令类型 | I1: 指令编号 | J1: 交货序号 | K1: 指令行号 | L1: 数量 | M1: 毛重 | N1: 重量单位 | O1: 体积 | P1: 指令来源 | Q1: 指令状态 | R1: 接口状态 | S1: 是否回传签收时间 | T1: 是否撤单 | U1: 移出物料 | V1: 移出物料描述 | W1: 厂商 | X1: 产品型号简称 | Y1: 产品类别描述 | Z1: 型号描述 | AA1: 颜色描述 | AB1: 物料计费类型 | AC1: 支付时间 | AD1: 波次号 | AE1: 拣选模式 | AF1: 拣货单号 | AG1: 播种位置 | AH1: 运单编号 | AI1: 运单创建时间 | AJ1: 运单出库时间 | AK1: 快递单编号 | AL1: 快递子单号 | AM1: 承运商名称 | AN1: 签收录入时间 | AO1: 纸质签收时间 | AP1: 签收人 | AQ1: 电子签时间 | AR1: 签收图片上传时 | AS1: 运单状态 | AT1: scm订单号 | AU1: 指令号+行号+交货序号 | AV1: 物流通知 | AW1: 外部接口物流信息 | AX1: 物流对象编码 | AY1: 物流对象描述 | AZ1: 售达方编号 | BA1: 售达方名称 | BB1: 零售分销标识 | BC1: 收货人 | BD1: 电话1 | BE1: 省份描述 | BF1: 城市描述 | BG1: 地区描述 | BH1: 区县内部划分 | BI1: 收货地址 | BJ1: 要求到货日期 | BK1: 拣配人 | BL1: 指令创建用户 | BM1: 指令下达时间 | BN1: 指令修改用户 | BO1: 指令修改日期 | BP1: 是否合约机 | BQ1: 要求发货时间 | BR1: 销售组织 | BS1: 异常消息
A2: {=_xlfn.IFS(AND(E2="104",F2="4400"),"深圳省仓",AND(E2="443",F2="4400"),"花都省仓",AND(E2="447",F2="4400"),"夏茅省仓",AND(E2="445",F2="4400"),"南沙省仓",AND(E2="448",F2="4400"),"中珠省仓",AND(E2="449",F2="4400"),"东莞省仓",AND(E2="440",F2="4400",G2<>"2352",BB2="A"),"零售电商仓",AND(E2="440",OR(F2="4400",F2="4450")),"增城省仓",AND(E2="441",F2="1000"),"互联网中心仓",E2="441","互联网省仓")} | B2: {=_xlfn.IFS(AB2="10-终端","手机",AB2="20-配件","配件",AB2="30-促销品","促销品",AB2="40-3C产品","多形态")} | C2: =L2+0 | D2: =E2&F2 | E2: 440 | F2: 4400 | G2: 2001 | H2: 11 | I2: 1169908500 | J2: 001 | K2: 000010 | L2: 1.0 | M2: 0.51 | N2: Kg | O2: 0.0 | P2: SCM | Q2: 已发运 | R2: 发货 | S2: 否 | T2: 否 | U2: 1B872154M11000L0 | V2: 荣耀_600 元气版 VKJ-AN90 12+512G,好事橙,512G,全网通,销售用机 | W2: 荣耀 | X2: 600 元气版 12+512G | Y2: 手机-其他 | Z2: 600 元气版 VKJ-AN90 12+512G | AA2: 好事橙 | AB2: 10-终端 | AD2: BC26062202195 | AE2: 边捡边播 | AF2: PK26062205352 | AG2: 7 | AH2: Z16045051194 | AI2: 2026-06-22 20:30:51 | AJ2: 2026-06-22 21:12:12 | AK2: JDV028096414962 | AM2: 北京京邦达贸易有限公司 | AS2: 出库完成 | AT2: 1062486796 | AU2: 1169908500000010001 | AV2: GD260622193615489 | AW2: FH-ZD-2606222012377141 | AX2: 0080475599 | AY2: 海丰县中移贸易有限公司 | AZ2: 0080475599 | BA2: 海丰县中移贸易有限公司 | BB2: B | BC2: 郑** | BD2: 157****4333 | BE2: 广东省 | BF2: 汕尾市 | BG2: 海丰县 | BH2: 一般地区 | BI2: [E]QC+********************************************************************************************************* | BJ2: 2026-06-24 18:00:00 | BK2: 杨磊 | BL2: 系统用户 | BM2: 2026-06-22 20:24:10 | BN2: 杨金凤 | BO2: 2026-06-22 21:12:17 | BP2: 否 | BR2: 4400

Sheet 广东省仓库存报表
A1: =TODAY()-1 | E1: 广东省仓&分仓库存报表
A2: 仓库 | B2: 种类 | D2: 总库存 | F2: 今日入库 | H2: 今日出库 | J2: 其中苹果产品库存情况
D3: 总量 | E3: SKU
A4: 手机 | C4: 总计 | D4: =D5+D6 | E4: =E5+E6 | F4: =F5+F6 | H4: =H5+H6 | J4: 单独苹果统计：苹果手表 373台，iPhone 15 4120台，iPhone 15 plus 10台，iPhone 16 1306台，iPhone 16 plus 109台，iPhone 16 pro 1310台， iPhone 16 Pro Max 1921台，合计9149台
C5: 省仓合计 | D5: =SUM(D7:D32) | E5: =SUMIFS(总库存!E:E,总库存!A:A,"增城省仓",总库存!B:B,"手机",总库存!E:E,1) | F5: =SUMIFS(收货记录查询!Y:Y,收货记录查询!A:A,"增城省仓",收货记录查询!B:B,"手机",收货记录查询!C:C,$A$1) | H5: =SUMIFS(出库全流程!C:C,出库全流程!A:A,"增城省仓",出库全流程!B:B,"手机")+SUMIFS(出库全流程!C:C,出库全流程!A:A,"零售电商仓",出库全流程!B:B,"手机")
C6: 分仓合计 | D6: =D46+D63+D69+D52+D74+D76 | E6: =SUMIFS(总库存!E:E,总库存!A:A,"深圳省仓",总库存!B:B,"手机",总库存!E:E,1)+SUMIFS(总库存!E:E,总库存!A:A,"花都省仓",总库存!B:B,"手机",总库存!E:E,1)+SUMIFS(总库存!E:E,总库存!A:A,"夏茅省仓",总库存!B:B,"手机",总库存!E:E,1)+SUMIFS(总库存!E:E,总库存!A:A,"南沙省仓",总库存!B:B,"手机",总库存!E:E,1)+SUMIFS(总库存!E:E,总库存!A:A,"中珠省仓",总库存!B:B,"手机",总库存!E:E,1)+SUMIFS(总库存!E:E,总库存!A:A,"东莞省仓",总库存!B:B,"手机",总库存!E:E,1) | F6: =SUMIFS(收货记录查询!Y:Y,收货记录查询!A:A,"深圳省仓",收货记录查询!B:B,"手机",收货记录查询!C:C,$A$1)+SUMIFS(收货记录查询!Y:Y,收货记录查询!A:A,"花都省仓",收货记录查询!B:B,"手机",收货记录查询!C:C,$A$1)+SUMIFS(收货记录查询!Y:Y,收货记录查询!A:A,"夏茅省仓",收货记录查询!B:B,"手机",收货记录查询!C:C,$A$1)+SUMIFS(收货记录查询!Y:Y,收货记录查询!A:A,"南沙省仓",收货记录查询!B:B,"手机",收货记录查询!C:C,$A$1)+SUMIFS(收货记录查询!Y:Y,收货记录查询!A:A,"中珠省仓",收货记录查询!B:B,"手机",收货记录查询!C:C,$A$1)+SUMIFS(收货记录查询!Y:Y,收货记录查询!A:A,"东莞省仓",收货记录查询!B:B,"手机",收货记录查询!C:C,$A$1) | H6: =SUMIFS(出库全流程!C:C,出库全流程!A:A,"深圳省仓",出库全流程!B:B,"手机")+SUMIFS(出库全流程!C:C,出库全流程!A:A,"花都省仓",出库全流程!B:B,"手机")+SUMIFS(出库全流程!C:C,出库全流程!A:A,"夏茅省仓",出库全流程!B:B,"手机")+SUMIFS(出库全流程!C:C,出库全流程!A:A,"南沙省仓",出库全流程!B:B,"手机")+SUMIFS(出库全流程!C:C,出库全流程!A:A,"中珠省仓",出库全流程!B:B,"手机")+SUMIFS(出库全流程!C:C,出库全流程!A:A,"东莞省仓",出库全流程!B:B,"手机")
A7: 增城省仓 （含零售B2C） | B7: 手机 | C7: 苹果 | D7: =SUMIFS(总库存!R:R,总库存!A:A,"增城省仓",总库存!B:B,"手机",总库存!U:U,C7) | E7: =SUMIFS(总库存!E:E,总库存!A:A,"增城省仓",总库存!B:B,"手机",总库存!U:U,C7,总库存!E:E,1) | F7: =SUMIFS(收货记录查询!Y:Y,收货记录查询!A:A,"增城省仓",收货记录查询!B:B,"手机",收货记录查询!M:M,C7,收货记录查询!C:C,$A$1) | H7: =SUMIFS(出库全流程!C:C,出库全流程!A:A,"增城省仓",出库全流程!B:B,"手机",出库全流程!W:W,C7)+SUMIFS(出库全流程!C:C,出库全流程!A:A,"零售电商仓",出库全流程!B:B,"手机",出库全流程!W:W,C7) | L7: 省仓库存合计（表格） | M7: =D5 | O7: 分仓库存合计（表格） | P7: =D6
C8: 华为 | D8: =SUMIFS(总库存!R:R,总库存!A:A,"增城省仓",总库存!B:B,"手机",总库存!U:U,C8) | E8: =SUMIFS(总库存!E:E,总库存!A:A,"增城省仓",总库存!B:B,"手机",总库存!U:U,C8,总库存!E:E,1) | F8: =SUMIFS(收货记录查询!Y:Y,收货记录查询!A:A,"增城省仓",收货记录查询!B:B,"手机",收货记录查询!M:M,C8,收货记录查询!C:C,$A$1) | H8: =SUMIFS(出库全流程!C:C,出库全流程!A:A,"增城省仓",出库全流程!B:B,"手机",出库全流程!W:W,C8)+SUMIFS(出库全流程!C:C,出库全流程!A:A,"零售电商仓",出库全流程!B:B,"手机",出库全流程!W:W,C8) | L8: 省仓库存合计（明细） | M8: =SUMIFS(总库存!R:R,总库存!A:A,"增城省仓",总库存!B:B,"手机") | O8: 分仓库存合计（明细） | P8: =SUMIFS(总库存!R:R,总库存!A:A,"深圳省仓",总库存!B:B,"手机")+SUMIFS(总库存!R:R,总库存!A:A,"夏茅省仓",总库存!B:B,"手机")+SUMIFS(总库存!R:R,总库存!A:A,"花都省仓",总库存!B:B,"手机")+SUMIFS(总库存!R:R,总库存!A:A,"南沙省仓",总库存!B:B,"手机")+SUMIFS(总库存!R:R,总库存!A:A,"中珠省仓",总库存!B:B,"手机")+SUMIFS(总库存!R:R,总库存!A:A,"东莞省仓",总库存!B:B,"手机")
C9: 维沃 | D9: =SUMIFS(总库存!R:R,总库存!A:A,"增城省仓",总库存!B:B,"手机",总库存!U:U,C9) | E9: =SUMIFS(总库存!E:E,总库存!A:A,"增城省仓",总库存!B:B,"手机",总库存!U:U,C9,总库存!E:E,1) | F9: =SUMIFS(收货记录查询!Y:Y,收货记录查询!A:A,"增城省仓",收货记录查询!B:B,"手机",收货记录查询!M:M,C9,收货记录查询!C:C,$A$1) | H9: =SUMIFS(出库全流程!C:C,出库全流程!A:A,"增城省仓",出库全流程!B:B,"手机",出库全流程!W:W,C9)+SUMIFS(出库全流程!C:C,出库全流程!A:A,"零售电商仓",出库全流程!B:B,"手机",出库全流程!W:W,C9) | L9: 差异数 | M9: =M7-M8 | O9: 差异数 | P9: =P7-P8
C10: 欧珀 | D10: =SUMIFS(总库存!R:R,总库存!A:A,"增城省仓",总库存!B:B,"手机",总库存!U:U,C10)+SUMIFS(总库存!R:R,总库存!A:A,"增城省仓",总库存!B:B,"手机",总库存!U:U,"remax") | E10: =SUMIFS(总库存!E:E,总库存!A:A,"增城省仓",总库存!B:B,"手机",总库存!U:U,C10,总库存!E:E,1)+SUMIFS(总库存!E:E,总库存!A:A,"增城省仓",总库存!B:B,"手机",总库存!U:U,"remax",总库存!E:E,1) | F10: =SUMIFS(收货记录查询!Y:Y,收货记录查询!A:A,"增城省仓",收货记录查询!B:B,"手机",收货记录查询!M:M,C10,收货记录查询!C:C,$A$1)+SUMIFS(收货记录查询!Y:Y,收货记录查询!A:A,"增城省仓",收货记录查询!B:B,"手机",收货记录查询!M:M,"remax",收货记录查询!C:C,$A$1) | H10: =SUMIFS(出库全流程!C:C,出库全流程!A:A,"增城省仓",出库全流程!B:B,"手机",出库全流程!W:W,C10)+SUMIFS(出库全流程!C:C,出库全流程!A:A,"零售电商仓",出库全流程!B:B,"手机",出库全流程!W:W,C10)+SUMIFS(出库全流程!C:C,出库全流程!A:A,"增城省仓",出库全流程!B:B,"手机",出库全流程!W:W,"remax")+SUMIFS(出库全流程!C:C,出库全流程!A:A,"零售电商仓",出库全流程!B:B,"手机",出库全流程!W:W,"remax") | L10: 注：如差异数不为0，则查看左侧表格是否需补充手机品牌，缺失品牌到子表[2.0总库存]查找
C11: 荣耀 | D11: =SUMIFS(总库存!R:R,总库存!A:A,"增城省仓",总库存!B:B,"手机",总库存!U:U,C11) | E11: =SUMIFS(总库存!E:E,总库存!A:A,"增城省仓",总库存!B:B,"手机",总库存!U:U,C11,总库存!E:E,1) | F11: =SUMIFS(收货记录查询!Y:Y,收货记录查询!A:A,"增城省仓",收货记录查询!B:B,"手机",收货记录查询!M:M,C11,收货记录查询!C:C,$A$1) | H11: =SUMIFS(出库全流程!C:C,出库全流程!A:A,"增城省仓",出库全流程!B:B,"手机",出库全流程!W:W,C11)+SUMIFS(出库全流程!C:C,出库全流程!A:A,"零售电商仓",出库全流程!B:B,"手机",出库全流程!W:W,C11)
C12: 小米科技 | D12: =SUMIFS(总库存!R:R,总库存!A:A,"增城省仓",总库存!B:B,"手机",总库存!U:U,C12) | E12: =SUMIFS(总库存!E:E,总库存!A:A,"增城省仓",总库存!B:B,"手机",总库存!U:U,C12,总库存!E:E,1) | F12: =SUMIFS(收货记录查询!Y:Y,收货记录查询!A:A,"增城省仓",收货记录查询!B:B,"手机",收货记录查询!M:M,C12,收货记录查询!C:C,$A$1) | H12: =SUMIFS(出库全流程!C:C,出库全流程!A:A,"增城省仓",出库全流程!B:B,"手机",出库全流程!W:W,C12)+SUMIFS(出库全流程!C:C,出库全流程!A:A,"零售电商仓",出库全流程!B:B,"手机",出库全流程!W:W,C12)
C13: REALME | D13: =SUMIFS(总库存!R:R,总库存!A:A,"增城省仓",总库存!B:B,"手机",总库存!U:U,C13) | E13: =SUMIFS(总库存!E:E,总库存!A:A,"增城省仓",总库存!B:B,"手机",总库存!U:U,C13,总库存!E:E,1) | F13: =SUMIFS(收货记录查询!Y:Y,收货记录查询!A:A,"增城省仓",收货记录查询!B:B,"手机",收货记录查询!M:M,C13,收货记录查询!C:C,$A$1) | H13: =SUMIFS(出库全流程!C:C,出库全流程!A:A,"增城省仓",出库全流程!B:B,"手机",出库全流程!W:W,C13)+SUMIFS(出库全流程!C:C,出库全流程!A:A,"零售电商仓",出库全流程!B:B,"手机",出库全流程!W:W,C13) | L13: 省仓入库合计（表格） | M13: =F5 | O13: 分仓入库合计（表格） | P13: =F6
C14: HI NOVA | D14: =SUMIFS(总库存!R:R,总库存!A:A,"增城省仓",总库存!B:B,"手机",总库存!U:U,C14) | E14: =SUMIFS(总库存!E:E,总库存!A:A,"增城省仓",总库存!B:B,"手机",总库存!U:U,C14,总库存!E:E,1) | F14: =SUMIFS(收货记录查询!Y:Y,收货记录查询!A:A,"增城省仓",收货记录查询!B:B,"手机",收货记录查询!M:M,C14,收货记录查询!C:C,$A$1) | H14: =SUMIFS(出库全流程!C:C,出库全流程!A:A,"增城省仓",出库全流程!B:B,"手机",出库全流程!W:W,C14)+SUMIFS(出库全流程!C:C,出库全流程!A:A,"零售电商仓",出库全流程!B:B,"手机",出库全流程!W:W,C14) | L14: 省仓入库合计（明细） | M14: =SUM(F7:G32) | O14: 分仓入库合计（明细） | P14: =F46+F63+F69+F52+F74+F77
C15: 中兴 | D15: =SUMIFS(总库存!R:R,总库存!A:A,"增城省仓",总库存!B:B,"手机",总库存!U:U,C15) | E15: =SUMIFS(总库存!E:E,总库存!A:A,"增城省仓",总库存!B:B,"手机",总库存!U:U,C15,总库存!E:E,1) | F15: =SUMIFS(收货记录查询!Y:Y,收货记录查询!A:A,"增城省仓",收货记录查询!B:B,"手机",收货记录查询!M:M,C15,收货记录查询!C:C,$A$1) | H15: =SUMIFS(出库全流程!C:C,出库全流程!A:A,"增城省仓",出库全流程!B:B,"手机",出库全流程!W:W,C15)+SUMIFS(出库全流程!C:C,出库全流程!A:A,"零售电商仓",出库全流程!B:B,"手机",出库全流程!W:W,C15) | L15: 差异数 | M15: =M13-M14 | O15: 差异数 | P15: =P13-P14
C16: 酷派 | D16: =SUMIFS(总库存!R:R,总库存!A:A,"增城省仓",总库存!B:B,"手机",总库存!U:U,C16) | E16: =SUMIFS(总库存!E:E,总库存!A:A,"增城省仓",总库存!B:B,"手机",总库存!U:U,C16,总库存!E:E,1) | F16: =SUMIFS(收货记录查询!Y:Y,收货记录查询!A:A,"增城省仓",收货记录查询!B:B,"手机",收货记录查询!M:M,C16,收货记录查询!C:C,$A$1) | H16: =SUMIFS(出库全流程!C:C,出库全流程!A:A,"增城省仓",出库全流程!B:B,"手机",出库全流程!W:W,C16)+SUMIFS(出库全流程!C:C,出库全流程!A:A,"零售电商仓",出库全流程!B:B,"手机",出库全流程!W:W,C16) | L16: 注：如差异数不为0，则查看左侧表格是否需补充手机品牌，缺失品牌到子表[2.0收货记录查询]查找
C17: 中国移动 | D17: =SUMIFS(总库存!R:R,总库存!A:A,"增城省仓",总库存!B:B,"手机",总库存!U:U,C17) | E17: =SUMIFS(总库存!E:E,总库存!A:A,"增城省仓",总库存!B:B,"手机",总库存!U:U,C17,总库存!E:E,1) | F17: =SUMIFS(收货记录查询!Y:Y,收货记录查询!A:A,"增城省仓",收货记录查询!B:B,"手机",收货记录查询!M:M,C17,收货记录查询!C:C,$A$1) | H17: =SUMIFS(出库全流程!C:C,出库全流程!A:A,"增城省仓",出库全流程!B:B,"手机",出库全流程!W:W,C17)+SUMIFS(出库全流程!C:C,出库全流程!A:A,"零售电商仓",出库全流程!B:B,"手机",出库全流程!W:W,C17)
C18: 一加 | D18: =SUMIFS(总库存!R:R,总库存!A:A,"增城省仓",总库存!B:B,"手机",总库存!U:U,C18) | E18: =SUMIFS(总库存!E:E,总库存!A:A,"增城省仓",总库存!B:B,"手机",总库存!U:U,C18,总库存!E:E,1) | F18: =SUMIFS(收货记录查询!Y:Y,收货记录查询!A:A,"增城省仓",收货记录查询!B:B,"手机",收货记录查询!M:M,C18,收货记录查询!C:C,$A$1) | H18: =SUMIFS(出库全流程!C:C,出库全流程!A:A,"增城省仓",出库全流程!B:B,"手机",出库全流程!W:W,C18)+SUMIFS(出库全流程!C:C,出库全流程!A:A,"零售电商仓",出库全流程!B:B,"手机",出库全流程!W:W,C18)
C19: 唯科 | D19: =SUMIFS(总库存!R:R,总库存!A:A,"增城省仓",总库存!B:B,"手机",总库存!U:U,C19) | E19: =SUMIFS(总库存!E:E,总库存!A:A,"增城省仓",总库存!B:B,"手机",总库存!U:U,C19,总库存!E:E,1) | F19: =SUMIFS(收货记录查询!Y:Y,收货记录查询!A:A,"增城省仓",收货记录查询!B:B,"手机",收货记录查询!M:M,C19,收货记录查询!C:C,$A$1) | H19: =SUMIFS(出库全流程!C:C,出库全流程!A:A,"增城省仓",出库全流程!B:B,"手机",出库全流程!W:W,C19)+SUMIFS(出库全流程!C:C,出库全流程!A:A,"零售电商仓",出库全流程!B:B,"手机",出库全流程!W:W,C19)
C20: TCL | D20: =SUMIFS(总库存!R:R,总库存!A:A,"增城省仓",总库存!B:B,"手机",总库存!U:U,C20) | E20: =SUMIFS(总库存!E:E,总库存!A:A,"增城省仓",总库存!B:B,"手机",总库存!U:U,C20,总库存!E:E,1) | F20: =SUMIFS(收货记录查询!Y:Y,收货记录查询!A:A,"增城省仓",收货记录查询!B:B,"手机",收货记录查询!M:M,C20,收货记录查询!C:C,$A$1) | H20: =SUMIFS(出库全流程!C:C,出库全流程!A:A,"增城省仓",出库全流程!B:B,"手机",出库全流程!W:W,C20)+SUMIFS(出库全流程!C:C,出库全流程!A:A,"零售电商仓",出库全流程!B:B,"手机",出库全流程!W:W,C20) | L20: 省仓出库合计（表格） | M20: =H5 | O20: 分仓出库合计（表格） | P20: =H6
C21: TOSOT | D21: =SUMIFS(总库存!R:R,总库存!A:A,"增城省仓",总库存!B:B,"手机",总库存!U:U,C21) | E21: =SUMIFS(总库存!E:E,总库存!A:A,"增城省仓",总库存!B:B,"手机",总库存!U:U,C21,总库存!E:E,1) | F21: =SUMIFS(收货记录查询!Y:Y,收货记录查询!A:A,"增城省仓",收货记录查询!B:B,"手机",收货记录查询!M:M,C21,收货记录查询!C:C,$A$1) | H21: =SUMIFS(出库全流程!C:C,出库全流程!A:A,"增城省仓",出库全流程!B:B,"手机",出库全流程!W:W,C21)+SUMIFS(出库全流程!C:C,出库全流程!A:A,"零售电商仓",出库全流程!B:B,"手机",出库全流程!W:W,C21) | L21: 省仓出库合计（明细） | M21: =SUM(H7:I32) | O21: 分仓出库合计（明细） | P21: =H46+H63+H69+H52+H74+H77
C22: 魅族 | D22: =SUMIFS(总库存!R:R,总库存!A:A,"增城省仓",总库存!B:B,"手机",总库存!U:U,C22) | E22: =SUMIFS(总库存!E:E,总库存!A:A,"增城省仓",总库存!B:B,"手机",总库存!U:U,C22,总库存!E:E,1) | F22: =SUMIFS(收货记录查询!Y:Y,收货记录查询!A:A,"增城省仓",收货记录查询!B:B,"手机",收货记录查询!M:M,C22,收货记录查询!C:C,$A$1) | H22: =SUMIFS(出库全流程!C:C,出库全流程!A:A,"增城省仓",出库全流程!B:B,"手机",出库全流程!W:W,C22)+SUMIFS(出库全流程!C:C,出库全流程!A:A,"零售电商仓",出库全流程!B:B,"手机",出库全流程!W:W,C22) | L22: 差异数 | M22: =M20-M21 | O22: 差异数 | P22: =P20-P21
C23: 金立 | D23: =SUMIFS(总库存!R:R,总库存!A:A,"增城省仓",总库存!B:B,"手机",总库存!U:U,C23) | E23: =SUMIFS(总库存!E:E,总库存!A:A,"增城省仓",总库存!B:B,"手机",总库存!U:U,C23,总库存!E:E,1) | F23: =SUMIFS(收货记录查询!Y:Y,收货记录查询!A:A,"增城省仓",收货记录查询!B:B,"手机",收货记录查询!M:M,C23,收货记录查询!C:C,$A$1) | H23: =SUMIFS(出库全流程!C:C,出库全流程!A:A,"增城省仓",出库全流程!B:B,"手机",出库全流程!W:W,C23)+SUMIFS(出库全流程!C:C,出库全流程!A:A,"零售电商仓",出库全流程!B:B,"手机",出库全流程!W:W,C23) | L23: 注：如差异数不为0，则查看左侧表格是否需补充手机品牌，缺失品牌到子表[2.0出库全流程]查找
C24: 中移终端公司 | D24: =SUMIFS(总库存!R:R,总库存!A:A,"增城省仓",总库存!B:B,"手机",总库存!U:U,C24) | E24: =SUMIFS(总库存!E:E,总库存!A:A,"增城省仓",总库存!B:B,"手机",总库存!U:U,C24,总库存!E:E,1) | F24: =SUMIFS(收货记录查询!Y:Y,收货记录查询!A:A,"增城省仓",收货记录查询!B:B,"手机",收货记录查询!M:M,C24,收货记录查询!C:C,$A$1) | H24: =SUMIFS(出库全流程!C:C,出库全流程!A:A,"增城省仓",出库全流程!B:B,"手机",出库全流程!W:W,C24)+SUMIFS(出库全流程!C:C,出库全流程!A:A,"零售电商仓",出库全流程!B:B,"手机",出库全流程!W:W,C24)
C25: 宇龙 | D25: =SUMIFS(总库存!R:R,总库存!A:A,"增城省仓",总库存!B:B,"手机",总库存!U:U,C25) | E25: =SUMIFS(总库存!E:E,总库存!A:A,"增城省仓",总库存!B:B,"手机",总库存!U:U,C25,总库存!E:E,1) | F25: =SUMIFS(收货记录查询!Y:Y,收货记录查询!A:A,"增城省仓",收货记录查询!B:B,"手机",收货记录查询!M:M,C25,收货记录查询!C:C,$A$1) | H25: =SUMIFS(出库全流程!C:C,出库全流程!A:A,"增城省仓",出库全流程!B:B,"手机",出库全流程!W:W,C25)+SUMIFS(出库全流程!C:C,出库全流程!A:A,"零售电商仓",出库全流程!B:B,"手机",出库全流程!W:W,C25)
C26: 弘米 | D26: =SUMIFS(总库存!R:R,总库存!A:A,"增城省仓",总库存!B:B,"手机",总库存!U:U,C26) | E26: =SUMIFS(总库存!E:E,总库存!A:A,"增城省仓",总库存!B:B,"手机",总库存!U:U,C26,总库存!E:E,1) | F26: =SUMIFS(收货记录查询!Y:Y,收货记录查询!A:A,"增城省仓",收货记录查询!B:B,"手机",收货记录查询!M:M,C26,收货记录查询!C:C,$A$1) | H26: =SUMIFS(出库全流程!C:C,出库全流程!A:A,"增城省仓",出库全流程!B:B,"手机",出库全流程!W:W,C26)+SUMIFS(出库全流程!C:C,出库全流程!A:A,"零售电商仓",出库全流程!B:B,"手机",出库全流程!W:W,C26)
C27: 联想 | D27: =SUMIFS(总库存!R:R,总库存!A:A,"增城省仓",总库存!B:B,"手机",总库存!U:U,C27) | E27: =SUMIFS(总库存!E:E,总库存!A:A,"增城省仓",总库存!B:B,"手机",总库存!U:U,C27,总库存!E:E,1) | F27: =SUMIFS(收货记录查询!Y:Y,收货记录查询!A:A,"增城省仓",收货记录查询!B:B,"手机",收货记录查询!M:M,C27,收货记录查询!C:C,$A$1) | H27: =SUMIFS(出库全流程!C:C,出库全流程!A:A,"增城省仓",出库全流程!B:B,"手机",出库全流程!W:W,C27)+SUMIFS(出库全流程!C:C,出库全流程!A:A,"零售电商仓",出库全流程!B:B,"手机",出库全流程!W:W,C27)
C28: 乐视 | D28: =SUMIFS(总库存!R:R,总库存!A:A,"增城省仓",总库存!B:B,"手机",总库存!U:U,C28) | E28: =SUMIFS(总库存!E:E,总库存!A:A,"增城省仓",总库存!B:B,"手机",总库存!U:U,C28,总库存!E:E,1) | F28: =SUMIFS(收货记录查询!Y:Y,收货记录查询!A:A,"增城省仓",收货记录查询!B:B,"手机",收货记录查询!M:M,C28,收货记录查询!C:C,$A$1) | H28: =SUMIFS(出库全流程!C:C,出库全流程!A:A,"增城省仓",出库全流程!B:B,"手机",出库全流程!W:W,C28)+SUMIFS(出库全流程!C:C,出库全流程!A:A,"零售电商仓",出库全流程!B:B,"手机",出库全流程!W:W,C28)
C29: iQOO | D29: =SUMIFS(总库存!R:R,总库存!A:A,"增城省仓",总库存!B:B,"手机",总库存!U:U,C29) | E29: =SUMIFS(总库存!E:E,总库存!A:A,"增城省仓",总库存!B:B,"手机",总库存!U:U,C29,总库存!E:E,1) | F29: =SUMIFS(收货记录查询!Y:Y,收货记录查询!A:A,"增城省仓",收货记录查询!B:B,"手机",收货记录查询!M:M,C29,收货记录查询!C:C,$A$1) | H29: =SUMIFS(出库全流程!C:C,出库全流程!A:A,"增城省仓",出库全流程!B:B,"手机",出库全流程!W:W,C29)+SUMIFS(出库全流程!C:C,出库全流程!A:A,"零售电商仓",出库全流程!B:B,"手机",出库全流程!W:W,C29)
C30: 依偎科技 | D30: =SUMIFS(总库存!R:R,总库存!A:A,"增城省仓",总库存!B:B,"手机",总库存!U:U,C30) | E30: =SUMIFS(总库存!E:E,总库存!A:A,"增城省仓",总库存!B:B,"手机",总库存!U:U,C30,总库存!E:E,1) | F30: =SUMIFS(收货记录查询!Y:Y,收货记录查询!A:A,"增城省仓",收货记录查询!B:B,"手机",收货记录查询!M:M,C30,收货记录查询!C:C,$A$1) | H30: =SUMIFS(出库全流程!C:C,出库全流程!A:A,"增城省仓",出库全流程!B:B,"手机",出库全流程!W:W,C30)+SUMIFS(出库全流程!C:C,出库全流程!A:A,"零售电商仓",出库全流程!B:B,"手机",出库全流程!W:W,C30)
C31: 摩托罗拉 | D31: =SUMIFS(总库存!R:R,总库存!A:A,"增城省仓",总库存!B:B,"手机",总库存!U:U,C31) | E31: =SUMIFS(总库存!E:E,总库存!A:A,"增城省仓",总库存!B:B,"手机",总库存!U:U,C31,总库存!E:E,1) | F31: =SUMIFS(收货记录查询!Y:Y,收货记录查询!A:A,"增城省仓",收货记录查询!B:B,"手机",收货记录查询!M:M,C31,收货记录查询!C:C,$A$1) | H31: =SUMIFS(出库全流程!C:C,出库全流程!A:A,"增城省仓",出库全流程!B:B,"手机",出库全流程!W:W,C31)+SUMIFS(出库全流程!C:C,出库全流程!A:A,"零售电商仓",出库全流程!B:B,"手机",出库全流程!W:W,C31)
C32: 三星 | D32: =SUMIFS(总库存!R:R,总库存!A:A,"增城省仓",总库存!B:B,"手机",总库存!U:U,C32)+SUMIFS(总库存!R:R,总库存!A:A,"增城省仓",总库存!B:B,"手机",总库存!U:U,"中国移动") | E32: =SUMIFS(总库存!E:E,总库存!A:A,"增城省仓",总库存!B:B,"手机",总库存!U:U,C32,总库存!E:E,1)+SUMIFS(总库存!E:E,总库存!A:A,"增城省仓",总库存!B:B,"手机",总库存!U:U,"中国移动",总库存!E:E,1) | F32: =SUMIFS(收货记录查询!Y:Y,收货记录查询!A:A,"增城省仓",收货记录查询!B:B,"手机",收货记录查询!M:M,C32,收货记录查询!C:C,$A$1) | H32: =SUMIFS(出库全流程!C:C,出库全流程!A:A,"增城省仓",出库全流程!B:B,"手机",出库全流程!W:W,C32)+SUMIFS(出库全流程!C:C,出库全流程!A:A,"零售电商仓",出库全流程!B:B,"手机",出库全流程!W:W,C32)+SUMIFS(出库全流程!C:C,出库全流程!A:A,"增城省仓",出库全流程!B:B,"手机",出库全流程!W:W,"中国移动")+SUMIFS(出库全流程!C:C,出库全流程!A:A,"零售电商仓",出库全流程!B:B,"手机",出库全流程!W:W,"中国移动")
B33: 多形态 | D33: =SUMIFS(总库存!R:R,总库存!A:A,"增城省仓",总库存!B:B,"多形态") | E33: =SUMIFS(总库存!E:E,总库存!A:A,"增城省仓",总库存!B:B,"多形态",总库存!E:E,1) | F33: =SUMIFS(收货记录查询!Y:Y,收货记录查询!A:A,"增城省仓",收货记录查询!B:B,"多形态",收货记录查询!C:C,$A$1) | H33: =SUMIFS(出库全流程!C:C,出库全流程!A:A,"增城省仓",出库全流程!B:B,B33)+SUMIFS(出库全流程!C:C,出库全流程!A:A,"零售电商仓",出库全流程!B:B,B33) | J33: =总库存!#REF!
B34: 配件 | D34: =SUMIFS(总库存!R:R,总库存!A:A,"增城省仓",总库存!B:B,"配件") | E34: =SUMIFS(总库存!E:E,总库存!A:A,"增城省仓",总库存!B:B,"配件",总库存!E:E,1) | F34: =SUMIFS(收货记录查询!Y:Y,收货记录查询!A:A,"增城省仓",收货记录查询!B:B,"配件",收货记录查询!C:C,$A$1) | H34: =SUMIFS(出库全流程!C:C,出库全流程!A:A,"增城省仓",出库全流程!B:B,B34) | J34: =总库存!#REF!
B35: 促销品 | D35: =SUMIFS(总库存!R:R,总库存!A:A,"增城省仓",总库存!B:B,"促销品") | E35: =SUMIFS(总库存!E:E,总库存!A:A,"增城省仓",总库存!B:B,"促销品",总库存!E:E,1) | F35: =SUMIFS(收货记录查询!Y:Y,收货记录查询!A:A,"增城省仓",收货记录查询!B:B,"促销品",收货记录查询!C:C,$A$1) | H35: =SUMIFS(出库全流程!C:C,出库全流程!A:A,"增城省仓",出库全流程!B:B,B35) | J35: =总库存!#REF!
B36: 宣传品 | D36: 0 | E36: 0 | F36: =SUMIFS(收货记录查询!Y:Y,收货记录查询!A:A,"增城省仓",收货记录查询!B:B,"促销品",收货记录查询!C:C,$A$1) | H36: 0 | J36: =总库存!#REF!
A37: 深圳省仓 | B37: 手机 | C37: 欧珀 | D37: =SUMIFS(总库存!R:R,总库存!A:A,"深圳省仓",总库存!B:B,"手机",总库存!U:U,C37)+SUMIFS(总库存!R:R,总库存!A:A,"深圳省仓",总库存!B:B,"手机",总库存!U:U,"REMAX") | E37: =SUMIFS(总库存!E:E,总库存!A:A,"深圳省仓",总库存!B:B,"手机",总库存!U:U,C37,总库存!E:E,1)+SUMIFS(总库存!E:E,总库存!A:A,"深圳省仓",总库存!B:B,"手机",总库存!U:U,"remax",总库存!E:E,1) | F37: =SUMIFS(收货记录查询!Y:Y,收货记录查询!A:A,"深圳省仓",收货记录查询!B:B,"手机",收货记录查询!M:M,C37,收货记录查询!C:C,$A$1)+SUMIFS(收货记录查询!Y:Y,收货记录查询!A:A,"深圳省仓",收货记录查询!B:B,"手机",收货记录查询!M:M,"remax",收货记录查询!C:C,$A$1) | H37: =SUMIFS(出库全流程!C:C,出库全流程!A:A,"深圳省仓",出库全流程!B:B,"手机",出库全流程!W:W,C37)+SUMIFS(出库全流程!C:C,出库全流程!A:A,"深圳省仓",出库全流程!B:B,"手机",出库全流程!W:W,"remax")
C38: 维沃 | D38: =SUMIFS(总库存!R:R,总库存!A:A,"深圳省仓",总库存!B:B,"手机",总库存!U:U,C38) | E38: =SUMIFS(总库存!E:E,总库存!A:A,"深圳省仓",总库存!B:B,"手机",总库存!U:U,C38,总库存!E:E,1) | F38: =SUMIFS(收货记录查询!Y:Y,收货记录查询!A:A,"深圳省仓",收货记录查询!B:B,"手机",收货记录查询!M:M,C38,收货记录查询!C:C,$A$1) | H38: =SUMIFS(出库全流程!C:C,出库全流程!A:A,"深圳省仓",出库全流程!B:B,"手机",出库全流程!W:W,C38)
C39: REALME | D39: =SUMIFS(总库存!R:R,总库存!A:A,"深圳省仓",总库存!B:B,"手机",总库存!U:U,C39) | E39: =SUMIFS(总库存!E:E,总库存!A:A,"深圳省仓",总库存!B:B,"手机",总库存!U:U,C39,总库存!E:E,1) | F39: =SUMIFS(收货记录查询!Y:Y,收货记录查询!A:A,"深圳省仓",收货记录查询!B:B,"手机",收货记录查询!M:M,C39,收货记录查询!C:C,$A$1) | H39: =SUMIFS(出库全流程!C:C,出库全流程!A:A,"深圳省仓",出库全流程!B:B,"手机",出库全流程!W:W,C39)
C40: 华为 | D40: =SUMIFS(总库存!R:R,总库存!A:A,"深圳省仓",总库存!B:B,"手机",总库存!U:U,C40) | E40: =SUMIFS(总库存!E:E,总库存!A:A,"深圳省仓",总库存!B:B,"手机",总库存!U:U,C40,总库存!E:E,1) | F40: =SUMIFS(收货记录查询!Y:Y,收货记录查询!A:A,"深圳省仓",收货记录查询!B:B,"手机",收货记录查询!M:M,C40,收货记录查询!C:C,$A$1) | H40: =SUMIFS(出库全流程!C:C,出库全流程!A:A,"深圳省仓",出库全流程!B:B,"手机",出库全流程!W:W,C40)
...

Sheet 广东省仓多形态库存报表
A1: =TODAY()-1 | E1: 广东省仓（含零售B2C）多形态库存报表
A2: 仓库 | B2: 种类 | D2: 总库存 | F2: 今日入库 | H2: 今日出库
D3: 总量 | E3: SKU
A4: 增城省仓 （含零售B2C） | B4: 多形态 | C4: 省仓合计 | D4: =SUMIFS(总库存!R:R,总库存!A:A,"增城省仓",总库存!B:B,"多形态") | E4: =SUMIFS(总库存!E:E,总库存!A:A,"增城省仓",总库存!B:B,"多形态",总库存!E:E,1) | F4: =SUMIFS(收货记录查询!Y:Y,收货记录查询!A:A,"增城省仓",收货记录查询!B:B,"多形态",收货记录查询!C:C,A1) | H4: =SUMIFS(出库全流程!C:C,出库全流程!A:A,"增城省仓",出库全流程!B:B,"多形态")+SUMIFS(出库全流程!C:C,出库全流程!A:A,"零售电商仓",出库全流程!B:B,"多形态")
C5: 中兴 | D5: =SUMIFS(总库存!R:R,总库存!A:A,"增城省仓",总库存!B:B,"多形态",总库存!U:U,C5) | E5: =SUMIFS(总库存!E:E,总库存!A:A,"增城省仓",总库存!B:B,"多形态",总库存!U:U,C5,总库存!E:E,1) | F5: =SUMIFS(收货记录查询!Y:Y,收货记录查询!A:A,"增城省仓",收货记录查询!B:B,"多形态",收货记录查询!M:M,C5,收货记录查询!C:C,$A$1) | H5: =SUMIFS(出库全流程!C:C,出库全流程!A:A,"增城省仓",出库全流程!B:B,"多形态",出库全流程!W:W,C5)+SUMIFS(出库全流程!C:C,出库全流程!A:A,"零售电商仓",出库全流程!B:B,"多形态",出库全流程!W:W,C5)
C6: 华为 | D6: =SUMIFS(总库存!R:R,总库存!A:A,"增城省仓",总库存!B:B,"多形态",总库存!U:U,C6) | E6: =SUMIFS(总库存!E:E,总库存!A:A,"增城省仓",总库存!B:B,"多形态",总库存!U:U,C6,总库存!E:E,1) | F6: =SUMIFS(收货记录查询!Y:Y,收货记录查询!A:A,"增城省仓",收货记录查询!B:B,"多形态",收货记录查询!M:M,C6,收货记录查询!C:C,$A$1) | H6: =SUMIFS(出库全流程!C:C,出库全流程!A:A,"增城省仓",出库全流程!B:B,"多形态",出库全流程!W:W,C6)+SUMIFS(出库全流程!C:C,出库全流程!A:A,"零售电商仓",出库全流程!B:B,"多形态",出库全流程!W:W,C6)
C7: TCL | D7: =SUMIFS(总库存!R:R,总库存!A:A,"增城省仓",总库存!B:B,"多形态",总库存!U:U,C7) | E7: =SUMIFS(总库存!E:E,总库存!A:A,"增城省仓",总库存!B:B,"多形态",总库存!U:U,C7,总库存!E:E,1) | F7: =SUMIFS(收货记录查询!Y:Y,收货记录查询!A:A,"增城省仓",收货记录查询!B:B,"多形态",收货记录查询!M:M,C7,收货记录查询!C:C,$A$1) | H7: =SUMIFS(出库全流程!C:C,出库全流程!A:A,"增城省仓",出库全流程!B:B,"多形态",出库全流程!W:W,C7)+SUMIFS(出库全流程!C:C,出库全流程!A:A,"零售电商仓",出库全流程!B:B,"多形态",出库全流程!W:W,C7)
C8: 康佳 | D8: =SUMIFS(总库存!R:R,总库存!A:A,"增城省仓",总库存!B:B,"多形态",总库存!U:U,C8) | E8: =SUMIFS(总库存!E:E,总库存!A:A,"增城省仓",总库存!B:B,"多形态",总库存!U:U,C8,总库存!E:E,1) | F8: =SUMIFS(收货记录查询!Y:Y,收货记录查询!A:A,"增城省仓",收货记录查询!B:B,"多形态",收货记录查询!M:M,C8,收货记录查询!C:C,$A$1) | H8: =SUMIFS(出库全流程!C:C,出库全流程!A:A,"增城省仓",出库全流程!B:B,"多形态",出库全流程!W:W,C8)+SUMIFS(出库全流程!C:C,出库全流程!A:A,"零售电商仓",出库全流程!B:B,"多形态",出库全流程!W:W,C8)
C9: 中移终端公司 | D9: =SUMIFS(总库存!R:R,总库存!A:A,"增城省仓",总库存!B:B,"多形态",总库存!U:U,C9) | E9: =SUMIFS(总库存!E:E,总库存!A:A,"增城省仓",总库存!B:B,"多形态",总库存!U:U,C9,总库存!E:E,1) | F9: =SUMIFS(收货记录查询!Y:Y,收货记录查询!A:A,"增城省仓",收货记录查询!B:B,"多形态",收货记录查询!M:M,C9,收货记录查询!C:C,$A$1) | H9: =SUMIFS(出库全流程!C:C,出库全流程!A:A,"增城省仓",出库全流程!B:B,"多形态",出库全流程!W:W,C9)+SUMIFS(出库全流程!C:C,出库全流程!A:A,"零售电商仓",出库全流程!B:B,"多形态",出库全流程!W:W,C9)
C10: 创维 | D10: =SUMIFS(总库存!R:R,总库存!A:A,"增城省仓",总库存!B:B,"多形态",总库存!U:U,C10) | E10: =SUMIFS(总库存!E:E,总库存!A:A,"增城省仓",总库存!B:B,"多形态",总库存!U:U,C10,总库存!E:E,1) | F10: =SUMIFS(收货记录查询!Y:Y,收货记录查询!A:A,"增城省仓",收货记录查询!B:B,"多形态",收货记录查询!M:M,C10,收货记录查询!C:C,$A$1) | H10: =SUMIFS(出库全流程!C:C,出库全流程!A:A,"增城省仓",出库全流程!B:B,"多形态",出库全流程!W:W,C10)+SUMIFS(出库全流程!C:C,出库全流程!A:A,"零售电商仓",出库全流程!B:B,"多形态",出库全流程!W:W,C10) | L10: 省仓库存合计（表格） | M10: =SUM(D5:D120)
C11: 中移物联网 | D11: =SUMIFS(总库存!R:R,总库存!A:A,"增城省仓",总库存!B:B,"多形态",总库存!U:U,C11) | E11: =SUMIFS(总库存!E:E,总库存!A:A,"增城省仓",总库存!B:B,"多形态",总库存!U:U,C11,总库存!E:E,1) | F11: =SUMIFS(收货记录查询!Y:Y,收货记录查询!A:A,"增城省仓",收货记录查询!B:B,"多形态",收货记录查询!M:M,C11,收货记录查询!C:C,$A$1) | H11: =SUMIFS(出库全流程!C:C,出库全流程!A:A,"增城省仓",出库全流程!B:B,"多形态",出库全流程!W:W,C11)+SUMIFS(出库全流程!C:C,出库全流程!A:A,"零售电商仓",出库全流程!B:B,"多形态",出库全流程!W:W,C11) | L11: 省仓库存合计（明细） | M11: =SUMIFS(总库存!R:R,总库存!A:A,"增城省仓",总库存!B:B,"多形态")
C12: 福建思特 | D12: =SUMIFS(总库存!R:R,总库存!A:A,"增城省仓",总库存!B:B,"多形态",总库存!U:U,C12) | E12: =SUMIFS(总库存!E:E,总库存!A:A,"增城省仓",总库存!B:B,"多形态",总库存!U:U,C12,总库存!E:E,1) | F12: =SUMIFS(收货记录查询!Y:Y,收货记录查询!A:A,"增城省仓",收货记录查询!B:B,"多形态",收货记录查询!M:M,C12,收货记录查询!C:C,$A$1) | H12: =SUMIFS(出库全流程!C:C,出库全流程!A:A,"增城省仓",出库全流程!B:B,"多形态",出库全流程!W:W,C12)+SUMIFS(出库全流程!C:C,出库全流程!A:A,"零售电商仓",出库全流程!B:B,"多形态",出库全流程!W:W,C12) | L12: 差异数 | M12: =M10-M11
C13: 乐心 | D13: =SUMIFS(总库存!R:R,总库存!A:A,"增城省仓",总库存!B:B,"多形态",总库存!U:U,C13) | E13: =SUMIFS(总库存!E:E,总库存!A:A,"增城省仓",总库存!B:B,"多形态",总库存!U:U,C13,总库存!E:E,1) | F13: =SUMIFS(收货记录查询!Y:Y,收货记录查询!A:A,"增城省仓",收货记录查询!B:B,"多形态",收货记录查询!M:M,C13,收货记录查询!C:C,$A$1) | H13: =SUMIFS(出库全流程!C:C,出库全流程!A:A,"增城省仓",出库全流程!B:B,"多形态",出库全流程!W:W,C13)+SUMIFS(出库全流程!C:C,出库全流程!A:A,"零售电商仓",出库全流程!B:B,"多形态",出库全流程!W:W,C13) | L13: 注：如差异数不为0，则查看左侧表格是否需补充多形态品牌，缺失品牌到子表[2.0总库存]查找
C14: 小米科技 | D14: =SUMIFS(总库存!R:R,总库存!A:A,"增城省仓",总库存!B:B,"多形态",总库存!U:U,C14) | E14: =SUMIFS(总库存!E:E,总库存!A:A,"增城省仓",总库存!B:B,"多形态",总库存!U:U,C14,总库存!E:E,1) | F14: =SUMIFS(收货记录查询!Y:Y,收货记录查询!A:A,"增城省仓",收货记录查询!B:B,"多形态",收货记录查询!M:M,C14,收货记录查询!C:C,$A$1) | H14: =SUMIFS(出库全流程!C:C,出库全流程!A:A,"增城省仓",出库全流程!B:B,"多形态",出库全流程!W:W,C14)+SUMIFS(出库全流程!C:C,出库全流程!A:A,"零售电商仓",出库全流程!B:B,"多形态",出库全流程!W:W,C14)
C15: 小天才 | D15: =SUMIFS(总库存!R:R,总库存!A:A,"增城省仓",总库存!B:B,"多形态",总库存!U:U,C15) | E15: =SUMIFS(总库存!E:E,总库存!A:A,"增城省仓",总库存!B:B,"多形态",总库存!U:U,C15,总库存!E:E,1) | F15: =SUMIFS(收货记录查询!Y:Y,收货记录查询!A:A,"增城省仓",收货记录查询!B:B,"多形态",收货记录查询!M:M,C15,收货记录查询!C:C,$A$1) | H15: =SUMIFS(出库全流程!C:C,出库全流程!A:A,"增城省仓",出库全流程!B:B,"多形态",出库全流程!W:W,C15)+SUMIFS(出库全流程!C:C,出库全流程!A:A,"零售电商仓",出库全流程!B:B,"多形态",出库全流程!W:W,C15)
C16: 数果 | D16: =SUMIFS(总库存!R:R,总库存!A:A,"增城省仓",总库存!B:B,"多形态",总库存!U:U,C16) | E16: =SUMIFS(总库存!E:E,总库存!A:A,"增城省仓",总库存!B:B,"多形态",总库存!U:U,C16,总库存!E:E,1) | F16: =SUMIFS(收货记录查询!Y:Y,收货记录查询!A:A,"增城省仓",收货记录查询!B:B,"多形态",收货记录查询!M:M,C16,收货记录查询!C:C,$A$1) | H16: =SUMIFS(出库全流程!C:C,出库全流程!A:A,"增城省仓",出库全流程!B:B,"多形态",出库全流程!W:W,C16)+SUMIFS(出库全流程!C:C,出库全流程!A:A,"零售电商仓",出库全流程!B:B,"多形态",出库全流程!W:W,C16) | L16: 省仓入库合计（表格） | M16: =SUM(F5:G120)
C17: 普联 | D17: =SUMIFS(总库存!R:R,总库存!A:A,"增城省仓",总库存!B:B,"多形态",总库存!U:U,C17) | E17: =SUMIFS(总库存!E:E,总库存!A:A,"增城省仓",总库存!B:B,"多形态",总库存!U:U,C17,总库存!E:E,1) | F17: =SUMIFS(收货记录查询!Y:Y,收货记录查询!A:A,"增城省仓",收货记录查询!B:B,"多形态",收货记录查询!M:M,C17,收货记录查询!C:C,$A$1) | H17: =SUMIFS(出库全流程!C:C,出库全流程!A:A,"增城省仓",出库全流程!B:B,"多形态",出库全流程!W:W,C17)+SUMIFS(出库全流程!C:C,出库全流程!A:A,"零售电商仓",出库全流程!B:B,"多形态",出库全流程!W:W,C17) | L17: 省仓入库合计（明细） | M17: =F4
C18: MAXHUB | D18: =SUMIFS(总库存!R:R,总库存!A:A,"增城省仓",总库存!B:B,"多形态",总库存!U:U,C18) | E18: =SUMIFS(总库存!E:E,总库存!A:A,"增城省仓",总库存!B:B,"多形态",总库存!U:U,C18,总库存!E:E,1) | F18: =SUMIFS(收货记录查询!Y:Y,收货记录查询!A:A,"增城省仓",收货记录查询!B:B,"多形态",收货记录查询!M:M,C18,收货记录查询!C:C,$A$1) | H18: =SUMIFS(出库全流程!C:C,出库全流程!A:A,"增城省仓",出库全流程!B:B,"多形态",出库全流程!W:W,C18)+SUMIFS(出库全流程!C:C,出库全流程!A:A,"零售电商仓",出库全流程!B:B,"多形态",出库全流程!W:W,C18) | L18: 差异数 | M18: =M16-M17
C19: 天波 | D19: =SUMIFS(总库存!R:R,总库存!A:A,"增城省仓",总库存!B:B,"多形态",总库存!U:U,C19) | E19: =SUMIFS(总库存!E:E,总库存!A:A,"增城省仓",总库存!B:B,"多形态",总库存!U:U,C19,总库存!E:E,1) | F19: =SUMIFS(收货记录查询!Y:Y,收货记录查询!A:A,"增城省仓",收货记录查询!B:B,"多形态",收货记录查询!M:M,C19,收货记录查询!C:C,$A$1) | H19: =SUMIFS(出库全流程!C:C,出库全流程!A:A,"增城省仓",出库全流程!B:B,"多形态",出库全流程!W:W,C19)+SUMIFS(出库全流程!C:C,出库全流程!A:A,"零售电商仓",出库全流程!B:B,"多形态",出库全流程!W:W,C19) | L19: 注：如差异数不为0，则查看左侧表格是否需补充多形态品牌，缺失品牌到子表[2.0收货记录查询]查找
C20: 欧珀 | D20: =SUMIFS(总库存!R:R,总库存!A:A,"增城省仓",总库存!B:B,"多形态",总库存!U:U,C20) | E20: =SUMIFS(总库存!E:E,总库存!A:A,"增城省仓",总库存!B:B,"多形态",总库存!U:U,C20,总库存!E:E,1) | F20: =SUMIFS(收货记录查询!Y:Y,收货记录查询!A:A,"增城省仓",收货记录查询!B:B,"多形态",收货记录查询!M:M,C20,收货记录查询!C:C,$A$1) | H20: =SUMIFS(出库全流程!C:C,出库全流程!A:A,"增城省仓",出库全流程!B:B,"多形态",出库全流程!W:W,C20)+SUMIFS(出库全流程!C:C,出库全流程!A:A,"零售电商仓",出库全流程!B:B,"多形态",出库全流程!W:W,C20)
C21: 杭州乐橙 | D21: =SUMIFS(总库存!R:R,总库存!A:A,"增城省仓",总库存!B:B,"多形态",总库存!U:U,C21) | E21: =SUMIFS(总库存!E:E,总库存!A:A,"增城省仓",总库存!B:B,"多形态",总库存!U:U,C21,总库存!E:E,1) | F21: =SUMIFS(收货记录查询!Y:Y,收货记录查询!A:A,"增城省仓",收货记录查询!B:B,"多形态",收货记录查询!M:M,C21,收货记录查询!C:C,$A$1) | H21: =SUMIFS(出库全流程!C:C,出库全流程!A:A,"增城省仓",出库全流程!B:B,"多形态",出库全流程!W:W,C21)+SUMIFS(出库全流程!C:C,出库全流程!A:A,"零售电商仓",出库全流程!B:B,"多形态",出库全流程!W:W,C21)
C22: 荣耀 | D22: =SUMIFS(总库存!R:R,总库存!A:A,"增城省仓",总库存!B:B,"多形态",总库存!U:U,C22) | E22: =SUMIFS(总库存!E:E,总库存!A:A,"增城省仓",总库存!B:B,"多形态",总库存!U:U,C22,总库存!E:E,1) | F22: =SUMIFS(收货记录查询!Y:Y,收货记录查询!A:A,"增城省仓",收货记录查询!B:B,"多形态",收货记录查询!M:M,C22,收货记录查询!C:C,$A$1) | H22: =SUMIFS(出库全流程!C:C,出库全流程!A:A,"增城省仓",出库全流程!B:B,"多形态",出库全流程!W:W,C22)+SUMIFS(出库全流程!C:C,出库全流程!A:A,"零售电商仓",出库全流程!B:B,"多形态",出库全流程!W:W,C22)
C23: 小度 | D23: =SUMIFS(总库存!R:R,总库存!A:A,"增城省仓",总库存!B:B,"多形态",总库存!U:U,C23) | E23: =SUMIFS(总库存!E:E,总库存!A:A,"增城省仓",总库存!B:B,"多形态",总库存!U:U,C23,总库存!E:E,1) | F23: =SUMIFS(收货记录查询!Y:Y,收货记录查询!A:A,"增城省仓",收货记录查询!B:B,"多形态",收货记录查询!M:M,C23,收货记录查询!C:C,$A$1) | H23: =SUMIFS(出库全流程!C:C,出库全流程!A:A,"增城省仓",出库全流程!B:B,"多形态",出库全流程!W:W,C23)+SUMIFS(出库全流程!C:C,出库全流程!A:A,"零售电商仓",出库全流程!B:B,"多形态",出库全流程!W:W,C23) | L23: 省仓出库合计（表格） | M23: =SUM(H5:I120)
C24: 涂鸦信息 | D24: =SUMIFS(总库存!R:R,总库存!A:A,"增城省仓",总库存!B:B,"多形态",总库存!U:U,C24) | E24: =SUMIFS(总库存!E:E,总库存!A:A,"增城省仓",总库存!B:B,"多形态",总库存!U:U,C24,总库存!E:E,1) | F24: =SUMIFS(收货记录查询!Y:Y,收货记录查询!A:A,"增城省仓",收货记录查询!B:B,"多形态",收货记录查询!M:M,C24,收货记录查询!C:C,$A$1) | H24: =SUMIFS(出库全流程!C:C,出库全流程!A:A,"增城省仓",出库全流程!B:B,"多形态",出库全流程!W:W,C24)+SUMIFS(出库全流程!C:C,出库全流程!A:A,"零售电商仓",出库全流程!B:B,"多形态",出库全流程!W:W,C24) | L24: 省仓出库合计（明细） | M24: =H4
C25: 萤石 | D25: =SUMIFS(总库存!R:R,总库存!A:A,"增城省仓",总库存!B:B,"多形态",总库存!U:U,C25) | E25: =SUMIFS(总库存!E:E,总库存!A:A,"增城省仓",总库存!B:B,"多形态",总库存!U:U,C25,总库存!E:E,1) | F25: =SUMIFS(收货记录查询!Y:Y,收货记录查询!A:A,"增城省仓",收货记录查询!B:B,"多形态",收货记录查询!M:M,C25,收货记录查询!C:C,$A$1) | H25: =SUMIFS(出库全流程!C:C,出库全流程!A:A,"增城省仓",出库全流程!B:B,"多形态",出库全流程!W:W,C25)+SUMIFS(出库全流程!C:C,出库全流程!A:A,"零售电商仓",出库全流程!B:B,"多形态",出库全流程!W:W,C25) | L25: 差异数 | M25: =M23-M24
C26: 万佳安 | D26: =SUMIFS(总库存!R:R,总库存!A:A,"增城省仓",总库存!B:B,"多形态",总库存!U:U,C26) | E26: =SUMIFS(总库存!E:E,总库存!A:A,"增城省仓",总库存!B:B,"多形态",总库存!U:U,C26,总库存!E:E,1) | F26: =SUMIFS(收货记录查询!Y:Y,收货记录查询!A:A,"增城省仓",收货记录查询!B:B,"多形态",收货记录查询!M:M,C26,收货记录查询!C:C,$A$1) | H26: =SUMIFS(出库全流程!C:C,出库全流程!A:A,"增城省仓",出库全流程!B:B,"多形态",出库全流程!W:W,C26)+SUMIFS(出库全流程!C:C,出库全流程!A:A,"零售电商仓",出库全流程!B:B,"多形态",出库全流程!W:W,C26) | L26: 注：如差异数不为0，则查看左侧表格是否需补充多形态品牌，缺失品牌到子表[2.0出库全流程]查找
C27: TP-LINK | D27: =SUMIFS(总库存!R:R,总库存!A:A,"增城省仓",总库存!B:B,"多形态",总库存!U:U,C27) | E27: =SUMIFS(总库存!E:E,总库存!A:A,"增城省仓",总库存!B:B,"多形态",总库存!U:U,C27,总库存!E:E,1) | F27: =SUMIFS(收货记录查询!Y:Y,收货记录查询!A:A,"增城省仓",收货记录查询!B:B,"多形态",收货记录查询!M:M,C27,收货记录查询!C:C,$A$1) | H27: =SUMIFS(出库全流程!C:C,出库全流程!A:A,"增城省仓",出库全流程!B:B,"多形态",出库全流程!W:W,C27)+SUMIFS(出库全流程!C:C,出库全流程!A:A,"零售电商仓",出库全流程!B:B,"多形态",出库全流程!W:W,C27)
C28: 视洞科技 | D28: =SUMIFS(总库存!R:R,总库存!A:A,"增城省仓",总库存!B:B,"多形态",总库存!U:U,C28) | E28: =SUMIFS(总库存!E:E,总库存!A:A,"增城省仓",总库存!B:B,"多形态",总库存!U:U,C28,总库存!E:E,1) | F28: =SUMIFS(收货记录查询!Y:Y,收货记录查询!A:A,"增城省仓",收货记录查询!B:B,"多形态",收货记录查询!M:M,C28,收货记录查询!C:C,$A$1) | H28: =SUMIFS(出库全流程!C:C,出库全流程!A:A,"增城省仓",出库全流程!B:B,"多形态",出库全流程!W:W,C28)+SUMIFS(出库全流程!C:C,出库全流程!A:A,"零售电商仓",出库全流程!B:B,"多形态",出库全流程!W:W,C28)
C29: 泉盛电子 | D29: =SUMIFS(总库存!R:R,总库存!A:A,"增城省仓",总库存!B:B,"多形态",总库存!U:U,C29) | E29: =SUMIFS(总库存!E:E,总库存!A:A,"增城省仓",总库存!B:B,"多形态",总库存!U:U,C29,总库存!E:E,1) | F29: =SUMIFS(收货记录查询!Y:Y,收货记录查询!A:A,"增城省仓",收货记录查询!B:B,"多形态",收货记录查询!M:M,C29,收货记录查询!C:C,$A$1) | H29: =SUMIFS(出库全流程!C:C,出库全流程!A:A,"增城省仓",出库全流程!B:B,"多形态",出库全流程!W:W,C29)+SUMIFS(出库全流程!C:C,出库全流程!A:A,"零售电商仓",出库全流程!B:B,"多形态",出库全流程!W:W,C29)
C30: 岭雁科技 | D30: =SUMIFS(总库存!R:R,总库存!A:A,"增城省仓",总库存!B:B,"多形态",总库存!U:U,C30) | E30: =SUMIFS(总库存!E:E,总库存!A:A,"增城省仓",总库存!B:B,"多形态",总库存!U:U,C30,总库存!E:E,1) | F30: =SUMIFS(收货记录查询!Y:Y,收货记录查询!A:A,"增城省仓",收货记录查询!B:B,"多形态",收货记录查询!M:M,C30,收货记录查询!C:C,$A$1) | H30: =SUMIFS(出库全流程!C:C,出库全流程!A:A,"增城省仓",出库全流程!B:B,"多形态",出库全流程!W:W,C30)+SUMIFS(出库全流程!C:C,出库全流程!A:A,"零售电商仓",出库全流程!B:B,"多形态",出库全流程!W:W,C30)
C31: 九安 | D31: =SUMIFS(总库存!R:R,总库存!A:A,"增城省仓",总库存!B:B,"多形态",总库存!U:U,C31) | E31: =SUMIFS(总库存!E:E,总库存!A:A,"增城省仓",总库存!B:B,"多形态",总库存!U:U,C31,总库存!E:E,1) | F31: =SUMIFS(收货记录查询!Y:Y,收货记录查询!A:A,"增城省仓",收货记录查询!B:B,"多形态",收货记录查询!M:M,C31,收货记录查询!C:C,$A$1) | H31: =SUMIFS(出库全流程!C:C,出库全流程!A:A,"增城省仓",出库全流程!B:B,"多形态",出库全流程!W:W,C31)+SUMIFS(出库全流程!C:C,出库全流程!A:A,"零售电商仓",出库全流程!B:B,"多形态",出库全流程!W:W,C31)
C32: 华为技术 | D32: =SUMIFS(总库存!R:R,总库存!A:A,"增城省仓",总库存!B:B,"多形态",总库存!U:U,C32) | E32: =SUMIFS(总库存!E:E,总库存!A:A,"增城省仓",总库存!B:B,"多形态",总库存!U:U,C32,总库存!E:E,1) | F32: =SUMIFS(收货记录查询!Y:Y,收货记录查询!A:A,"增城省仓",收货记录查询!B:B,"多形态",收货记录查询!M:M,C32,收货记录查询!C:C,$A$1) | H32: =SUMIFS(出库全流程!C:C,出库全流程!A:A,"增城省仓",出库全流程!B:B,"多形态",出库全流程!W:W,C32)+SUMIFS(出库全流程!C:C,出库全流程!A:A,"零售电商仓",出库全流程!B:B,"多形态",出库全流程!W:W,C32)
C33: 英飞拓 | D33: =SUMIFS(总库存!R:R,总库存!A:A,"增城省仓",总库存!B:B,"多形态",总库存!U:U,C33) | E33: =SUMIFS(总库存!E:E,总库存!A:A,"增城省仓",总库存!B:B,"多形态",总库存!U:U,C33,总库存!E:E,1) | F33: =SUMIFS(收货记录查询!Y:Y,收货记录查询!A:A,"增城省仓",收货记录查询!B:B,"多形态",收货记录查询!M:M,C33,收货记录查询!C:C,$A$1) | H33: =SUMIFS(出库全流程!C:C,出库全流程!A:A,"增城省仓",出库全流程!B:B,"多形态",出库全流程!W:W,C33)+SUMIFS(出库全流程!C:C,出库全流程!A:A,"零售电商仓",出库全流程!B:B,"多形态",出库全流程!W:W,C33)
C34: 华橙网络 | D34: =SUMIFS(总库存!R:R,总库存!A:A,"增城省仓",总库存!B:B,"多形态",总库存!U:U,C34) | E34: =SUMIFS(总库存!E:E,总库存!A:A,"增城省仓",总库存!B:B,"多形态",总库存!U:U,C34,总库存!E:E,1) | F34: =SUMIFS(收货记录查询!Y:Y,收货记录查询!A:A,"增城省仓",收货记录查询!B:B,"多形态",收货记录查询!M:M,C34,收货记录查询!C:C,$A$1) | H34: =SUMIFS(出库全流程!C:C,出库全流程!A:A,"增城省仓",出库全流程!B:B,"多形态",出库全流程!W:W,C34)+SUMIFS(出库全流程!C:C,出库全流程!A:A,"零售电商仓",出库全流程!B:B,"多形态",出库全流程!W:W,C34)
C35: 巨峰 | D35: =SUMIFS(总库存!R:R,总库存!A:A,"增城省仓",总库存!B:B,"多形态",总库存!U:U,C35) | E35: =SUMIFS(总库存!E:E,总库存!A:A,"增城省仓",总库存!B:B,"多形态",总库存!U:U,C35,总库存!E:E,1) | F35: =SUMIFS(收货记录查询!Y:Y,收货记录查询!A:A,"增城省仓",收货记录查询!B:B,"多形态",收货记录查询!M:M,C35,收货记录查询!C:C,$A$1) | H35: =SUMIFS(出库全流程!C:C,出库全流程!A:A,"增城省仓",出库全流程!B:B,"多形态",出库全流程!W:W,C35)+SUMIFS(出库全流程!C:C,出库全流程!A:A,"零售电商仓",出库全流程!B:B,"多形态",出库全流程!W:W,C35)
C36: 极联 | D36: =SUMIFS(总库存!R:R,总库存!A:A,"增城省仓",总库存!B:B,"多形态",总库存!U:U,C36) | E36: =SUMIFS(总库存!E:E,总库存!A:A,"增城省仓",总库存!B:B,"多形态",总库存!U:U,C36,总库存!E:E,1) | F36: =SUMIFS(收货记录查询!Y:Y,收货记录查询!A:A,"增城省仓",收货记录查询!B:B,"多形态",收货记录查询!M:M,C36,收货记录查询!C:C,$A$1) | H36: =SUMIFS(出库全流程!C:C,出库全流程!A:A,"增城省仓",出库全流程!B:B,"多形态",出库全流程!W:W,C36)+SUMIFS(出库全流程!C:C,出库全流程!A:A,"零售电商仓",出库全流程!B:B,"多形态",出库全流程!W:W,C36)
C37: 英得尔 | D37: =SUMIFS(总库存!R:R,总库存!A:A,"增城省仓",总库存!B:B,"多形态",总库存!U:U,C37) | E37: =SUMIFS(总库存!E:E,总库存!A:A,"增城省仓",总库存!B:B,"多形态",总库存!U:U,C37,总库存!E:E,1) | F37: =SUMIFS(收货记录查询!Y:Y,收货记录查询!A:A,"增城省仓",收货记录查询!B:B,"多形态",收货记录查询!M:M,C37,收货记录查询!C:C,$A$1) | H37: =SUMIFS(出库全流程!C:C,出库全流程!A:A,"增城省仓",出库全流程!B:B,"多形态",出库全流程!W:W,C37)+SUMIFS(出库全流程!C:C,出库全流程!A:A,"零售电商仓",出库全流程!B:B,"多形态",出库全流程!W:W,C37)
C38: ENABOT | D38: =SUMIFS(总库存!R:R,总库存!A:A,"增城省仓",总库存!B:B,"多形态",总库存!U:U,C38) | E38: =SUMIFS(总库存!E:E,总库存!A:A,"增城省仓",总库存!B:B,"多形态",总库存!U:U,C38,总库存!E:E,1) | F38: =SUMIFS(收货记录查询!Y:Y,收货记录查询!A:A,"增城省仓",收货记录查询!B:B,"多形态",收货记录查询!M:M,C38,收货记录查询!C:C,$A$1) | H38: =SUMIFS(出库全流程!C:C,出库全流程!A:A,"增城省仓",出库全流程!B:B,"多形态",出库全流程!W:W,C38)+SUMIFS(出库全流程!C:C,出库全流程!A:A,"零售电商仓",出库全流程!B:B,"多形态",出库全流程!W:W,C38)
... C120: 赛达科技 | D120: =SUMIFS(总库存!R:R,总库存!A:A,"增城省仓",总库存!B:B,"多形态",总库存!U:U,C120) | E120: =SUMIFS(总库存!E:E,总库存!A:A,"增城省仓",总库存!B:B,"多形态",总库存!U:U,C120,总库存!E:E,1) | F120: =SUMIFS(收货记录查询!Y:Y,收货记录查询!A:A,"增城省仓",收货记录查询!B:B,"多形态",收货记录查询!M:M,C120,收货记录查询!C:C,$A$1) | H120: =SUMIFS(出库全流程!C:C,出库全流程!A:A,"增城省仓",出库全流程!B:B,"多形态",出库全流程!W:W,C120)+SUMIFS(出库全流程!C:C,出库全流程!A:A,"零售电商仓",出库全流程!B:B,"多形态",出库全流程!W:W,C120)
A121: 数据来源： | D121: LIS库存查询汇总 | F121: LIS收货记录查询 | H121: LIS出库全流程单据清单
...

Sheet 互联网省仓库存报表
A1: =TODAY()-1 | D1: 互联网省仓库存报表
A2: 仓库 | B2: 种类 | D2: 总库存 | F2: 今日入库 | H2: 今日出库
D3: 总量 | E3: SKU
A4: 互联网 省仓 | B4: 手机 | C4: 总计 | D4: =SUM(D5:D17) | E4: =SUM(E5:E17) | F4: =SUM(F5:G17) | H4: =SUM(H5:I17) | K4: 省仓库存合计（表格） | L4: =D4
C5: 苹果 | D5: =SUMIFS(总库存!R:R,总库存!A:A,"互联网省仓",总库存!B:B,"手机",总库存!U:U,C5) | E5: =SUMIFS(总库存!E:E,总库存!A:A,"互联网省仓",总库存!B:B,"手机",总库存!U:U,C5,总库存!E:E,1) | F5: =SUMIFS(收货记录查询!Y:Y,收货记录查询!A:A,"互联网省仓",收货记录查询!B:B,"手机",收货记录查询!M:M,C5,收货记录查询!C:C,$A$1) | H5: =SUMIFS(出库全流程!C:C,出库全流程!A:A,"互联网省仓",出库全流程!B:B,"手机",出库全流程!W:W,C5) | K5: 省仓库存合计（明细） | L5: =SUMIFS(总库存!R:R,总库存!A:A,"互联网省仓",总库存!B:B,"手机")
C6: 华为 | D6: =SUMIFS(总库存!R:R,总库存!A:A,"互联网省仓",总库存!B:B,"手机",总库存!U:U,C6) | E6: =SUMIFS(总库存!E:E,总库存!A:A,"互联网省仓",总库存!B:B,"手机",总库存!U:U,C6,总库存!E:E,1) | F6: =SUMIFS(收货记录查询!Y:Y,收货记录查询!A:A,"互联网省仓",收货记录查询!B:B,"手机",收货记录查询!M:M,C6,收货记录查询!C:C,$A$1) | H6: =SUMIFS(出库全流程!C:C,出库全流程!A:A,"互联网省仓",出库全流程!B:B,"手机",出库全流程!W:W,C6) | K6: 差异数 | L6: =L4-L5
C7: 小米科技 | D7: =SUMIFS(总库存!R:R,总库存!A:A,"互联网省仓",总库存!B:B,"手机",总库存!U:U,C7) | E7: =SUMIFS(总库存!E:E,总库存!A:A,"互联网省仓",总库存!B:B,"手机",总库存!U:U,C7,总库存!E:E,1) | F7: =SUMIFS(收货记录查询!Y:Y,收货记录查询!A:A,"互联网省仓",收货记录查询!B:B,"手机",收货记录查询!M:M,C7,收货记录查询!C:C,$A$1) | H7: =SUMIFS(出库全流程!C:C,出库全流程!A:A,"互联网省仓",出库全流程!B:B,"手机",出库全流程!W:W,C7) | K7: 注：如差异数不为0，则查看左侧表格是否需补充手机品牌，缺失品牌到子表[2.0总库存]查找
C8: 欧珀 | D8: =SUMIFS(总库存!R:R,总库存!A:A,"互联网省仓",总库存!B:B,"手机",总库存!U:U,C8)+SUMIFS(总库存!R:R,总库存!A:A,"互联网省仓",总库存!B:B,"手机",总库存!U:U,"remax") | E8: =SUMIFS(总库存!E:E,总库存!A:A,"互联网省仓",总库存!B:B,"手机",总库存!U:U,C8,总库存!E:E,1) | F8: =SUMIFS(收货记录查询!Y:Y,收货记录查询!A:A,"互联网省仓",收货记录查询!B:B,"手机",收货记录查询!M:M,C8,收货记录查询!C:C,$A$1)+SUMIFS(收货记录查询!Y:Y,收货记录查询!A:A,"互联网省仓",收货记录查询!B:B,"手机",收货记录查询!M:M,"remax",收货记录查询!C:C,$A$1) | H8: =SUMIFS(出库全流程!C:C,出库全流程!A:A,"互联网省仓",出库全流程!B:B,"手机",出库全流程!W:W,C8)+SUMIFS(出库全流程!C:C,出库全流程!A:A,"互联网省仓",出库全流程!B:B,"手机",出库全流程!W:W,"remax")
C9: iQOO | D9: =SUMIFS(总库存!R:R,总库存!A:A,"互联网省仓",总库存!B:B,"手机",总库存!U:U,C9) | E9: =SUMIFS(总库存!E:E,总库存!A:A,"互联网省仓",总库存!B:B,"手机",总库存!U:U,C9,总库存!E:E,1) | F9: =SUMIFS(收货记录查询!Y:Y,收货记录查询!A:A,"互联网省仓",收货记录查询!B:B,"手机",收货记录查询!M:M,C9,收货记录查询!C:C,$A$1)+SUMIFS(收货记录查询!Y:Y,收货记录查询!A:A,"互联网省仓",收货记录查询!B:B,"手机",收货记录查询!M:M,"remax",收货记录查询!C:C,$A$1) | H9: =SUMIFS(出库全流程!C:C,出库全流程!A:A,"互联网省仓",出库全流程!B:B,"手机",出库全流程!W:W,C9)+SUMIFS(出库全流程!C:C,出库全流程!A:A,"互联网省仓",出库全流程!B:B,"手机",出库全流程!W:W,"remax")
C10: 荣耀 | D10: =SUMIFS(总库存!R:R,总库存!A:A,"互联网省仓",总库存!B:B,"手机",总库存!U:U,C10) | E10: =SUMIFS(总库存!E:E,总库存!A:A,"互联网省仓",总库存!B:B,"手机",总库存!U:U,C10,总库存!E:E,1) | F10: =SUMIFS(收货记录查询!Y:Y,收货记录查询!A:A,"互联网省仓",收货记录查询!B:B,"手机",收货记录查询!M:M,C10,收货记录查询!C:C,$A$1) | H10: =SUMIFS(出库全流程!C:C,出库全流程!A:A,"互联网省仓",出库全流程!B:B,"手机",出库全流程!W:W,C10)
C11: 魅族 | D11: =SUMIFS(总库存!R:R,总库存!A:A,"互联网省仓",总库存!B:B,"手机",总库存!U:U,C11) | E11: =SUMIFS(总库存!E:E,总库存!A:A,"互联网省仓",总库存!B:B,"手机",总库存!U:U,C11,总库存!E:E,1) | F11: =SUMIFS(收货记录查询!Y:Y,收货记录查询!A:A,"互联网省仓",收货记录查询!B:B,"手机",收货记录查询!M:M,C11,收货记录查询!C:C,$A$1) | H11: =SUMIFS(出库全流程!C:C,出库全流程!A:A,"互联网省仓",出库全流程!B:B,"手机",出库全流程!W:W,C11) | K11: 省仓入库合计（表格） | L11: =F4
C12: 维沃 | D12: =SUMIFS(总库存!R:R,总库存!A:A,"互联网省仓",总库存!B:B,"手机",总库存!U:U,C12) | E12: =SUMIFS(总库存!E:E,总库存!A:A,"互联网省仓",总库存!B:B,"手机",总库存!U:U,C12,总库存!E:E,1) | F12: =SUMIFS(收货记录查询!Y:Y,收货记录查询!A:A,"互联网省仓",收货记录查询!B:B,"手机",收货记录查询!M:M,C12,收货记录查询!C:C,$A$1) | H12: =SUMIFS(出库全流程!C:C,出库全流程!A:A,"互联网省仓",出库全流程!B:B,"手机",出库全流程!W:W,C12) | K12: 省仓入库合计（明细） | L12: =SUMIFS(收货记录查询!Y:Y,收货记录查询!A:A,"互联网省仓",收货记录查询!B:B,"手机",收货记录查询!C:C,$A$1)
C13: 一加 | D13: =SUMIFS(总库存!R:R,总库存!A:A,"互联网省仓",总库存!B:B,"手机",总库存!U:U,C13) | E13: =SUMIFS(总库存!E:E,总库存!A:A,"互联网省仓",总库存!B:B,"手机",总库存!U:U,C13,总库存!E:E,1) | F13: =SUMIFS(收货记录查询!Y:Y,收货记录查询!A:A,"互联网省仓",收货记录查询!B:B,"手机",收货记录查询!M:M,C13,收货记录查询!C:C,$A$1) | H13: =SUMIFS(出库全流程!C:C,出库全流程!A:A,"互联网省仓",出库全流程!B:B,"手机",出库全流程!W:W,C13) | K13: 差异数 | L13: =L11-L12
C14: REALME | D14: =SUMIFS(总库存!R:R,总库存!A:A,"互联网省仓",总库存!B:B,"手机",总库存!U:U,C14) | E14: =SUMIFS(总库存!E:E,总库存!A:A,"互联网省仓",总库存!B:B,"手机",总库存!U:U,C14,总库存!E:E,1) | F14: =SUMIFS(收货记录查询!Y:Y,收货记录查询!A:A,"互联网省仓",收货记录查询!B:B,"手机",收货记录查询!M:M,C14,收货记录查询!C:C,$A$1) | H14: =SUMIFS(出库全流程!C:C,出库全流程!A:A,"互联网省仓",出库全流程!B:B,"手机",出库全流程!W:W,C14) | K14: 注：如差异数不为0，则查看左侧表格是否需补充手机品牌，缺失品牌到子表[2.0收货记录查询]查找
C15: 三星 | D15: =SUMIFS(总库存!R:R,总库存!A:A,"互联网省仓",总库存!B:B,"手机",总库存!U:U,C15)+SUMIFS(总库存!R:R,总库存!A:A,"互联网省仓",总库存!B:B,"手机",总库存!U:U,"中国移动") | E15: =SUMIFS(总库存!E:E,总库存!A:A,"互联网省仓",总库存!B:B,"手机",总库存!U:U,C15,总库存!E:E,1)+SUMIFS(总库存!E:E,总库存!A:A,"互联网省仓",总库存!B:B,"手机",总库存!U:U,"中国移动",总库存!E:E,1) | F15: =SUMIFS(收货记录查询!Y:Y,收货记录查询!A:A,"互联网省仓",收货记录查询!B:B,"手机",收货记录查询!M:M,C15,收货记录查询!C:C,$A$1)+SUMIFS(收货记录查询!Y:Y,收货记录查询!A:A,"互联网省仓",收货记录查询!B:B,"手机",收货记录查询!M:M,"中国移动",收货记录查询!C:C,$A$1) | H15: =SUMIFS(出库全流程!C:C,出库全流程!A:A,"互联网省仓",出库全流程!B:B,"手机",出库全流程!W:W,C15)+SUMIFS(出库全流程!C:C,出库全流程!A:A,"互联网省仓",出库全流程!B:B,"手机",出库全流程!W:W,"中国移动")
C16: 酷派 | D16: =SUMIFS(总库存!R:R,总库存!A:A,"互联网省仓",总库存!B:B,"手机",总库存!U:U,C16) | E16: =SUMIFS(总库存!E:E,总库存!A:A,"互联网省仓",总库存!B:B,"手机",总库存!U:U,C16,总库存!E:E,1)+SUMIFS(总库存!E:E,总库存!A:A,"互联网省仓",总库存!B:B,"手机",总库存!U:U,"中国移动",总库存!E:E,1) | F16: =SUMIFS(收货记录查询!Y:Y,收货记录查询!A:A,"互联网省仓",收货记录查询!B:B,"手机",收货记录查询!M:M,C16,收货记录查询!C:C,$A$1) | H16: =SUMIFS(出库全流程!C:C,出库全流程!A:A,"互联网省仓",出库全流程!B:B,"手机",出库全流程!W:W,C16)
C17: 中移终端公司 | D17: =SUMIFS(总库存!R:R,总库存!A:A,"互联网省仓",总库存!B:B,"手机",总库存!U:U,C17) | E17: =SUMIFS(总库存!E:E,总库存!A:A,"互联网省仓",总库存!B:B,"手机",总库存!U:U,C17,总库存!E:E,1)+SUMIFS(总库存!E:E,总库存!A:A,"互联网省仓",总库存!B:B,"手机",总库存!U:U,"中国移动",总库存!E:E,1) | F17: =SUMIFS(收货记录查询!Y:Y,收货记录查询!A:A,"互联网省仓",收货记录查询!B:B,"手机",收货记录查询!M:M,C17,收货记录查询!C:C,$A$1) | H17: =SUMIFS(出库全流程!C:C,出库全流程!A:A,"互联网省仓",出库全流程!B:B,"手机",出库全流程!W:W,C17)
B18: 多形态 | D18: =SUMIFS(总库存!R:R,总库存!A:A,"互联网省仓",总库存!B:B,"多形态") | E18: =SUMIFS(总库存!E:E,总库存!A:A,"互联网省仓",总库存!B:B,"多形态",总库存!E:E,1) | F18: =SUMIFS(收货记录查询!Y:Y,收货记录查询!A:A,"互联网省仓",收货记录查询!B:B,"多形态",收货记录查询!C:C,$A$1) | H18: =SUMIFS(出库全流程!C:C,出库全流程!A:A,"互联网省仓",出库全流程!B:B,B18) | K18: 省仓出库合计（表格） | L18: =H4
B19: 配件 | D19: =SUMIFS(总库存!R:R,总库存!A:A,"互联网省仓",总库存!B:B,"配件") | E19: =SUMIFS(总库存!E:E,总库存!A:A,"互联网省仓",总库存!B:B,"配件",总库存!E:E,1) | F19: =SUMIFS(收货记录查询!Y:Y,收货记录查询!A:A,"互联网省仓",收货记录查询!B:B,"配件",收货记录查询!C:C,$A$1) | H19: =SUMIFS(出库全流程!C:C,出库全流程!A:A,"互联网省仓",出库全流程!B:B,B19) | K19: 省仓出库合计（明细） | L19: =SUMIFS(出库全流程!C:C,出库全流程!A:A,"互联网省仓",出库全流程!B:B,"手机")
B20: 促销品 | D20: =SUMIFS(总库存!R:R,总库存!A:A,"互联网省仓",总库存!B:B,"促销品") | E20: =SUMIFS(总库存!E:E,总库存!A:A,"互联网省仓",总库存!B:B,"促销品",总库存!E:E,1) | F20: =SUMIFS(收货记录查询!Y:Y,收货记录查询!A:A,"互联网省仓",收货记录查询!B:B,"促销品",收货记录查询!C:C,$A$1) | H20: =SUMIFS(出库全流程!C:C,出库全流程!A:A,"互联网省仓",出库全流程!B:B,B20) | K20: 差异数 | L20: =L18-L19
A21: 数据来源： | D21: LIS库存查询汇总 | F21: LIS收货记录查询 | H21: LIS出库全流程单据清单 | K21: 注：如差异数不为0，则查看左侧表格是否需补充手机品牌，缺失品牌到子表[2.0出库全流程]查找
A22: 数据周期： | D22: 实时库存数 | F22: =$A$1 | G22: 00:00-24:00 | H22: =$A$1 | I22: 6:00-次日6:00

Sheet 互联网中心仓库存报表
A1: =TODAY()-1 | D1: 互联网中心仓库存报表
A2: 仓库 | B2: 种类 | D2: 总库存 | F2: 今日入库 | H2: 今日出库
D3: 总量 | E3: SKU
A4: 互联网 中心仓 | B4: 手机 | C4: 总计 | D4: =SUM(D5:D14) | E4: =SUM(E5:E14) | F4: =SUM(F5:F14) | H4: =SUM(H5:I14) | K4: 中心仓库存合计（表格） | L4: =D4
C5: 华为 | D5: =SUMIFS(总库存!R:R,总库存!A:A,"互联网中心仓",总库存!B:B,"手机",总库存!U:U,C5) | E5: =SUMIFS(总库存!E:E,总库存!A:A,"互联网中心仓",总库存!B:B,"手机",总库存!U:U,C5,总库存!E:E,1) | F5: =SUMIFS(收货记录查询!Y:Y,收货记录查询!A:A,"互联网中心仓",收货记录查询!B:B,"手机",收货记录查询!M:M,C5,收货记录查询!C:C,$A$1) | H5: =SUMIFS(出库全流程!C:C,出库全流程!A:A,"互联网中心仓",出库全流程!B:B,"手机",出库全流程!W:W,C5) | K5: 中心仓库存合计（明细） | L5: =SUMIFS(总库存!R:R,总库存!A:A,"互联网中心仓",总库存!B:B,"手机")
C6: 小米科技 | D6: =SUMIFS(总库存!R:R,总库存!A:A,"互联网中心仓",总库存!B:B,"手机",总库存!U:U,C6) | E6: =SUMIFS(总库存!E:E,总库存!A:A,"互联网中心仓",总库存!B:B,"手机",总库存!U:U,C6,总库存!E:E,1) | F6: =SUMIFS(收货记录查询!Y:Y,收货记录查询!A:A,"互联网中心仓",收货记录查询!B:B,"手机",收货记录查询!M:M,C6,收货记录查询!C:C,$A$1) | H6: =SUMIFS(出库全流程!C:C,出库全流程!A:A,"互联网中心仓",出库全流程!B:B,"手机",出库全流程!W:W,C6) | K6: 差异数 | L6: =L4-L5
C7: 欧珀 | D7: =SUMIFS(总库存!R:R,总库存!A:A,"互联网中心仓",总库存!B:B,"手机",总库存!U:U,C7)+SUMIFS(总库存!R:R,总库存!A:A,"互联网中心仓",总库存!B:B,"手机",总库存!U:U,"remax") | E7: =SUMIFS(总库存!E:E,总库存!A:A,"互联网中心仓",总库存!B:B,"手机",总库存!U:U,C7,总库存!E:E,1) | F7: =SUMIFS(收货记录查询!Y:Y,收货记录查询!A:A,"互联网中心仓",收货记录查询!B:B,"手机",收货记录查询!M:M,C7,收货记录查询!C:C,$A$1)+SUMIFS(收货记录查询!Y:Y,收货记录查询!A:A,"互联网中心仓",收货记录查询!B:B,"手机",收货记录查询!M:M,"remax",收货记录查询!C:C,$A$1) | H7: =SUMIFS(出库全流程!C:C,出库全流程!A:A,"互联网中心仓",出库全流程!B:B,"手机",出库全流程!W:W,C7)+SUMIFS(出库全流程!C:C,出库全流程!A:A,"互联网中心仓",出库全流程!B:B,"手机",出库全流程!W:W,"remax") | K7: 注：如差异数不为0，则查看左侧表格是否需补充手机品牌，缺失品牌到子表[2.0总库存]查找
C8: 苹果 | D8: =SUMIFS(总库存!R:R,总库存!A:A,"互联网中心仓",总库存!B:B,"手机",总库存!U:U,C8) | E8: =SUMIFS(总库存!E:E,总库存!A:A,"互联网中心仓",总库存!B:B,"手机",总库存!U:U,C8,总库存!E:E,1) | F8: =SUMIFS(收货记录查询!Y:Y,收货记录查询!A:A,"互联网中心仓",收货记录查询!B:B,"手机",收货记录查询!M:M,C8,收货记录查询!C:C,$A$1) | H8: =SUMIFS(出库全流程!C:C,出库全流程!A:A,"互联网中心仓",出库全流程!B:B,"手机",出库全流程!W:W,C8)
C9: iQOO | D9: =SUMIFS(总库存!R:R,总库存!A:A,"互联网中心仓",总库存!B:B,"手机",总库存!U:U,C9) | E9: =SUMIFS(总库存!E:E,总库存!A:A,"互联网中心仓",总库存!B:B,"手机",总库存!U:U,C9,总库存!E:E,1) | F9: =SUMIFS(收货记录查询!Y:Y,收货记录查询!A:A,"互联网中心仓",收货记录查询!B:B,"手机",收货记录查询!M:M,C9,收货记录查询!C:C,$A$1) | H9: =SUMIFS(出库全流程!C:C,出库全流程!A:A,"互联网中心仓",出库全流程!B:B,"手机",出库全流程!W:W,C9)
C10: 维沃 | D10: =SUMIFS(总库存!R:R,总库存!A:A,"互联网中心仓",总库存!B:B,"手机",总库存!U:U,C10) | E10: =SUMIFS(总库存!E:E,总库存!A:A,"互联网中心仓",总库存!B:B,"手机",总库存!U:U,C10,总库存!E:E,1) | F10: =SUMIFS(收货记录查询!Y:Y,收货记录查询!A:A,"互联网中心仓",收货记录查询!B:B,"手机",收货记录查询!M:M,C10,收货记录查询!C:C,$A$1) | H10: =SUMIFS(出库全流程!C:C,出库全流程!A:A,"互联网中心仓",出库全流程!B:B,"手机",出库全流程!W:W,C10)
C11: 一加 | D11: =SUMIFS(总库存!R:R,总库存!A:A,"互联网中心仓",总库存!B:B,"手机",总库存!U:U,C11) | E11: =SUMIFS(总库存!E:E,总库存!A:A,"互联网中心仓",总库存!B:B,"手机",总库存!U:U,C11,总库存!E:E,1) | F11: =SUMIFS(收货记录查询!Y:Y,收货记录查询!A:A,"互联网中心仓",收货记录查询!B:B,"手机",收货记录查询!M:M,C11,收货记录查询!C:C,$A$1) | H11: =SUMIFS(出库全流程!C:C,出库全流程!A:A,"互联网中心仓",出库全流程!B:B,"手机",出库全流程!W:W,C11) | K11: 中心仓入库合计（表格） | L11: =F4
C12: 荣耀 | D12: =SUMIFS(总库存!R:R,总库存!A:A,"互联网中心仓",总库存!B:B,"手机",总库存!U:U,C12) | E12: =SUMIFS(总库存!E:E,总库存!A:A,"互联网中心仓",总库存!B:B,"手机",总库存!U:U,C12,总库存!E:E,1) | F12: =SUMIFS(收货记录查询!Y:Y,收货记录查询!A:A,"互联网中心仓",收货记录查询!B:B,"手机",收货记录查询!M:M,C12,收货记录查询!C:C,$A$1) | H12: =SUMIFS(出库全流程!C:C,出库全流程!A:A,"互联网中心仓",出库全流程!B:B,"手机",出库全流程!W:W,C12) | K12: 中心仓入库合计（明细） | L12: =SUMIFS(收货记录查询!Y:Y,收货记录查询!A:A,"互联网中心仓",收货记录查询!B:B,"手机",收货记录查询!C:C,$A$1)
C13: REALME | D13: =SUMIFS(总库存!R:R,总库存!A:A,"互联网中心仓",总库存!B:B,"手机",总库存!U:U,C13) | E13: =SUMIFS(总库存!E:E,总库存!A:A,"互联网中心仓",总库存!B:B,"手机",总库存!U:U,C13,总库存!E:E,1) | F13: =SUMIFS(收货记录查询!Y:Y,收货记录查询!A:A,"互联网中心仓",收货记录查询!B:B,"手机",收货记录查询!M:M,C13,收货记录查询!C:C,$A$1) | H13: =SUMIFS(出库全流程!C:C,出库全流程!A:A,"互联网中心仓",出库全流程!B:B,"手机",出库全流程!W:W,C13) | K13: 差异数 | L13: =L11-L12
C14: 中移终端公司 | D14: =SUMIFS(总库存!R:R,总库存!A:A,"互联网中心仓",总库存!B:B,"手机",总库存!U:U,C14) | E14: =SUMIFS(总库存!E:E,总库存!A:A,"互联网中心仓",总库存!B:B,"手机",总库存!U:U,C14,总库存!E:E,1) | F14: =SUMIFS(收货记录查询!Y:Y,收货记录查询!A:A,"互联网中心仓",收货记录查询!B:B,"手机",收货记录查询!M:M,C14,收货记录查询!C:C,$A$1) | H14: =SUMIFS(出库全流程!C:C,出库全流程!A:A,"互联网中心仓",出库全流程!B:B,"手机",出库全流程!W:W,C14) | K14: 注：如差异数不为0，则查看左侧表格是否需补充手机品牌，缺失品牌到子表[2.0收货记录查询]查找
B15: 多形态 | D15: =SUMIFS(总库存!R:R,总库存!A:A,"互联网中心仓",总库存!B:B,"多形态") | E15: =SUMIFS(总库存!E:E,总库存!A:A,"互联网中心仓",总库存!B:B,"多形态",总库存!E:E,1) | F15: =SUMIFS(收货记录查询!Y:Y,收货记录查询!A:A,"互联网中心仓",收货记录查询!B:B,"多形态",收货记录查询!C:C,$A$1) | H15: =SUMIFS(出库全流程!C:C,出库全流程!A:A,"互联网中心仓",出库全流程!B:B,B15)
B16: 配件 | D16: =SUMIFS(总库存!R:R,总库存!A:A,"互联网中心仓",总库存!B:B,"配件") | E16: =SUMIFS(总库存!E:E,总库存!A:A,"互联网中心仓",总库存!B:B,"配件",总库存!E:E,1) | F16: =SUMIFS(收货记录查询!Y:Y,收货记录查询!A:A,"互联网中心仓",收货记录查询!B:B,"配件",收货记录查询!C:C,$A$1) | H16: =SUMIFS(出库全流程!C:C,出库全流程!A:A,"互联网中心仓",出库全流程!B:B,B16)
B17: 促销品 | D17: =SUMIFS(总库存!R:R,总库存!A:A,"互联网中心仓",总库存!B:B,"促销品") | E17: =SUMIFS(总库存!E:E,总库存!A:A,"互联网中心仓",总库存!B:B,"促销品",总库存!E:E,1) | F17: =SUMIFS(收货记录查询!Y:Y,收货记录查询!A:A,"互联网中心仓",收货记录查询!B:B,"促销品",收货记录查询!C:C,$A$1) | H17: =SUMIFS(出库全流程!C:C,出库全流程!A:A,"互联网中心仓",出库全流程!B:B,B17) | K17: 中心仓出库合计（表格） | L17: =H4
A18: 数据来源： | D18: LIS库存查询汇总 | F18: LIS收货记录查询 | H18: LIS出库全流程单据清单 | K18: 中心仓出库合计（明细） | L18: =SUMIFS(出库全流程!C:C,出库全流程!A:A,"互联网中心仓",出库全流程!B:B,"手机")
A19: 数据周期： | D19: 实时库存数 | F19: =$A$1 | G19: 00:00-24:00 | H19: =$A$1 | I19: 6:00-次日6:00 | K19: 差异数 | L19: =L17-L18
K20: 注：如差异数不为0，则查看左侧表格是否需补充手机品牌，缺失品牌到子表[2.0出库全流程]查找

Sheet 出库全流程高级筛选
A1: 发货仓库 | B1: 移出货主 | C1: 移出库存地 | D1: 指令类型 | E1: 指令编号 | F1: 交货序号 | G1: 指令行号 | H1: 数量 | I1: 毛重 | J1: 重量单位 | K1: 体积 | L1: 指令来源 | M1: 指令状态 | N1: 接口状态 | O1: 是否回传签收时间 | P1: 是否撤单 | Q1: 移出物料 | R1: 移出物料描述 | S1: 厂商 | T1: 产品型号简称 | U1: 产品类别描述 | V1: 型号描述 | W1: 颜色描述 | X1: 物料计费类型 | Y1: 支付时间 | Z1: 波次号 | AA1: 拣选模式 | AB1: 拣货单号 | AC1: 播种位置 | AD1: 运单编号 | AE1: 运单创建时间 | AF1: 运单出库时间 | AG1: 快递单编号 | AH1: 快递子单号 | AI1: 承运商名称 | AJ1: 签收录入时间 | AK1: 纸质签收时间 | AL1: 签收人 | AM1: 电子签时间 | AN1: 签收图片上传时 | AO1: 运单状态 | AP1: scm订单号 | AQ1: 指令号+行号+交货序号 | AR1: 物流通知 | AS1: 外部接口物流信息 | AT1: 物流对象编码 | AU1: 物流对象描述 | AV1: 售达方编号 | AW1: 售达方名称 | AX1: 零售分销标识 | AY1: 收货人 | AZ1: 电话1 | BA1: 省份描述 | BB1: 城市描述 | BC1: 地区描述 | BD1: 区县内部划分 | BE1: 收货地址 | BF1: 要求到货日期 | BG1: 拣配人 | BH1: 指令创建用户 | BI1: 指令下达时间 | BJ1: 指令修改用户 | BK1: 指令修改日期 | BL1: 是否合约机 | BM1: 要求发货时间 | BN1: 销售组织 | BO1: 异常消息

Sheet 收货记录查询高级筛选
A1: 操作时间 | B1: 仓库 | C1: 货主 | D1: 库存地点 | E1: 指令编号 | F1: 指令行项 | G1: 物料编码 | H1: 物料描述 | I1: 厂商 | J1: 产品型号简称 | K1: 物料计费类型 | L1: 确认状态 | M1: 移动方向 | N1: 移动类型 | O1: 特殊库存 | P1: 特殊库存编号 | Q1: 批次号 | R1: 目的存储类型 | S1: 目的仓位 | T1: 目的存储单元编号 | U1: 源数量 | V1: 确认数量 | W1: 确认差异数量 | X1: 单位 | Y1: 用户 | Z1: 供应商 | AA1: 转储需求编号 | AB1: 订单号 | AC1: 采购订单行号 | AD1: 修改日期 | AE1: 修改用户 | AF1: 创建日期 | AG1: 创建用户

Sheet 制表步骤
A1: 1.【入库管理】-[收货记录查询]，操作时间选昨天，查询，导出(全量数据），切换不同仓库重复查询导出操作,使用高级筛选功能转换成子表[收货记录查询高级筛选]中的表头---将转换后的明细复制到[2.0收货记录查询] | B1: 注意1：操作时间挪至表头第一位 | C1: 注意2：导出5个不同仓库的表格后合并在一个表中，与报表【业务简报】可共用
A2: 2.【综合查询】-[库存查询汇总]查询，导出（全量数据）---复制到[2.0总库存] | B2: 注意：与报表【库存5品牌】可共用
A3: 3.【综合查询】-[出库全流程单据清单]，运单出库时间昨天6:00-次日6:00，查询，导出（全量数据）,使用高级筛选功能转换成子表[出库全流程高级筛选]中的表头---将转换后的明细复制到[2.0出库全流程] | B3: 注意：与报表【业务简报】可共用
A4: 4.复制完需要把公式填充完整，检查公式是否正确
A6: a.导网页CT的广东终端仓库，在库的 机模 和 宣传物料 修改整理跟表里格式一样（一周导一次）
A8: 报表发送方式：【广东终端信息反馈群】发送图片及表格文件

Sheet 匹配条件
D1: 仓库名称 | E1: 仓库 | F1: 货主编码(工厂编码) | G1: 库存地点 | H1: 业务归属1 | I1: 业务归属2 | J1: 库存归属 | K1: 业务归属
D2: 广东广州市省仓(科捷) | E2: 440 | F2: 4400 | G2: 2001 | H2: =D2&F2&G2 | I2: =E2&F2 | J2: 增城省仓 | K2: =D2&F2
D3: 广东广州市省仓(科捷) | E3: 440 | F3: 4400 | G3: 2004 | H3: =D3&F3&G3 | I3: =E3&F3 | J3: 增城省仓 | K3: =D3&F3
D4: 广东广州市省仓(科捷) | E4: 440 | F4: 4400 | G4: 2049 | H4: =D4&F4&G4 | I4: =E4&F4 | J4: 增城省仓 | K4: =D4&F4
D5: 广东广州市省仓(科捷) | E5: 440 | F5: 4400 | G5: 2061 | H5: =D5&F5&G5 | I5: =E5&F5 | J5: 增城省仓 | K5: =D5&F5
D6: 广东广州市省仓(科捷) | E6: 440 | F6: 4400 | G6: 2065 | H6: =D6&F6&G6 | I6: =E6&F6 | J6: 增城省仓 | K6: =D6&F6
D7: 广东广州市省仓(科捷) | E7: 440 | F7: 4400 | G7: 2088 | H7: =D7&F7&G7 | I7: =E7&F7 | J7: 增城省仓 | K7: =D7&F7
D8: 广东广州市省仓(科捷) | E8: 440 | F8: 4400 | G8: 2094 | H8: =D8&F8&G8 | I8: =E8&F8 | J8: 增城省仓 | K8: =D8&F8
D9: 广东广州市省仓(科捷) | E9: 440 | F9: 4400 | G9: 2097 | H9: =D9&F9&G9 | I9: =E9&F9 | J9: 增城省仓 | K9: =D9&F9
D10: 广东广州市省仓(科捷) | E10: 440 | F10: 4400 | G10: 2098 | H10: =D10&F10&G10 | I10: =E10&F10 | J10: 增城省仓 | K10: =D10&F10
D11: 广东广州市省仓(科捷) | E11: 440 | F11: 4400 | G11: 2102 | H11: =D11&F11&G11 | I11: =E11&F11 | J11: 增城省仓 | K11: =D11&F11
D12: 广东广州市省仓(科捷) | E12: 440 | F12: 4400 | G12: 2105 | H12: =D12&F12&G12 | I12: =E12&F12 | J12: 增城省仓 | K12: =D12&F12
D13: 广东广州市省仓(科捷) | E13: 440 | F13: 4400 | G13: 2200 | H13: =D13&F13&G13 | I13: =E13&F13 | J13: 增城省仓 | K13: =D13&F13
... D74: 总部深圳通用总仓(科捷) | E74: 104 | F74: 4400 | G74: 2353 | H74: =D74&F74&G74 | I74: =E74&F74 | J74: 深圳省仓 | K74: =D74&F74
D75: 广东OPPO花都省仓(科捷) | E75: 443 | F75: 4400 | G75: 2365 | H75: =D75&F75&G75 | I75: =E75&F75 | J75: 花都省仓 | K75: =D75&F75
D76: 广东OPPO花都省仓(科捷) | E76: 443 | F76: 4400 | G76: 2364 | H76: =D76&F76&G76 | I76: =E76&F76 | J76: 花都省仓 | K76: =D76&F76
D77: 广东OPPO花都省仓(科捷) | E77: 443 | F77: 4400 | G77: 2361 | H77: =D77&F77&G77 | I77: =E77&F77 | J77: 花都省仓 | K77: =D77&F77
D78: 广东OPPO花都省仓(科捷) | E78: 443 | F78: 4400 | G78: 2359 | H78: =D78&F78&G78 | I78: =E78&F78 | J78: 花都省仓 | K78: =D78&F78
D79: 广东OPPO花都省仓(科捷) | E79: 443 | F79: 4400 | G79: 2360 | H79: =D79&F79&G79 | I79: =E79&F79 | J79: 花都省仓 | K79: =D79&F79
D80: 广东OPPO花都省仓(科捷) | E80: 443 | F80: 4400 | G80: 2358 | H80: =D80&F80&G80 | I80: =E80&F80 | J80: 花都省仓 | K80: =D80&F80
D81: 广东OPPO花都省仓(科捷) | E81: 443 | F81: 4400 | G81: 2347 | H81: =D81&F81&G81 | I81: =E81&F81 | J81: 花都省仓 | K81: =D81&F81
D82: 广东OPPO花都省仓(科捷) | E82: 443 | F82: 4400 | G82: 2348 | H82: =D82&F82&G82 | I82: =E82&F82 | J82: 花都省仓 | K82: =D82&F82
D83: 广东OPPO花都省仓(科捷) | E83: 443 | F83: 4400 | G83: 2329 | H83: =D83&F83&G83 | I83: =E83&F83 | J83: 花都省仓 | K83: =D83&F83
D84: 广东OPPO花都省仓(科捷) | E84: 443 | F84: 4400 | G84: 2330 | H84: =D84&F84&G84 | I84: =E84&F84 | J84: 花都省仓 | K84: =D84&F84
D85: 广东广州市省仓(科捷) | E85: 440 | F85: 4450 | G85: 2001 | H85: =D85&F85&G85 | I85: =E85&F85 | J85: 增城省仓 | K85: =D85&F85
D86: 广东广州市省仓(科捷) | E86: 440 | F86: 4450 | G86: 2004 | H86: =D86&F86&G86 | I86: =E86&F86 | J86: 增城省仓 | K86: =D86&F86
D87: 广东广州市省仓(科捷) | E87: 440 | F87: 4450 | G87: 2049 | H87: =D87&F87&G87 | I87: =E87&F87 | J87: 增城省仓 | K87: =D87&F87
D88: 广东广州市省仓(科捷) | E88: 440 | F88: 4450 | G88: 2061 | H88: =D88&F88&G88 | I88: =E88&F88 | J88: 增城省仓 | K88: =D88&F88
D89: 广东广州市省仓(科捷) | E89: 440 | F89: 4450 | G89: 2065 | H89: =D89&F89&G89 | I89: =E89&F89 | J89: 增城省仓 | K89: =D89&F89
D90: 广东广州市省仓(科捷) | E90: 440 | F90: 4450 | G90: 2088 | H90: =D90&F90&G90 | I90: =E90&F90 | J90: 增城省仓 | K90: =D90&F90
D91: 广东广州市省仓(科捷) | E91: 440 | F91: 4450 | G91: 2094 | H91: =D91&F91&G91 | I91: =E91&F91 | J91: 增城省仓 | K91: =D91&F91
D92: 广东广州市省仓(科捷) | E92: 440 | F92: 4450 | G92: 2097 | H92: =D92&F92&G92 | I92: =E92&F92 | J92: 增城省仓 | K92: =D92&F92
D93: 广东广州市省仓(科捷) | E93: 440 | F93: 4450 | G93: 2098 | H93: =D93&F93&G93 | I93: =E93&F93 | J93: 增城省仓 | K93: =D93&F93
D94: 广东广州市省仓(科捷) | E94: 440 | F94: 4450 | G94: 2102 | H94: =D94&F94&G94 | I94: =E94&F94 | J94: 增城省仓 | K94: =D94&F94
D95: 广东广州市省仓(科捷) | E95: 440 | F95: 4450 | G95: 2105 | H95: =D95&F95&G95 | I95: =E95&F95 | J95: 增城省仓 | K95: =D95&F95
D96: 广东广州市省仓(科捷) | E96: 440 | F96: 4450 | G96: 2200 | H96: =D96&F96&G96 | I96: =E96&F96 | J96: 增城省仓 | K96: =D96&F96
... D124: 广东广州市省仓(科捷) | E124: 440 | F124: 4450 | G124: S202 | H124: =D124&F124&G124 | I124: =E124&F124 | J124: 增城省仓 | K124: =D124&F124
D125: 广东广州市省仓(科捷) | E125: 440 | F125: 9320 | G125: SH50 | H125: =D125&F125&G125 | I125: =E125&F125 | J125: 外部业务 | K125: =D125&F125
D126: 广东广州市省仓(科捷) | E126: 440 | F126: 9320 | G126: SH49 | H126: =D126&F126&G126 | I126: =E126&F126 | J126: 外部业务 | K126: =D126&F126
D127: 广东广州市省仓(科捷) | E127: 440 | F127: 9320 | G127: SH48 | H127: =D127&F127&G127 | I127: =E127&F127 | J127: 外部业务 | K127: =D127&F127
...
